Workbook

Sheet Leia-me
A1: Controle tributário familiar — Simples Nacional / Fator R
A3: Como usar
A4: 1. Aba Parâmetros: confira alíquotas, CLT, dependentes e os 3 cenários de pró-labore.
A5: 2. Aba Notas: preencha o NOME de cada empresa (linha amarela) e o VALOR da nota mês a mês.
A6: 3. Aba Simulação: calcula automaticamente receita, Fator R (12 meses), anexo, DAS, INSS, IRRF, lucro isento e líquido familiar.
A7: 4. Aba Comparativo: resume o ano e mostra qual cenário fica mais barato.
A9: Cores
A10: Amarelo = campo editável (você preenche).
A11: Cinza = campo calculado (não editar).
A12: Verde = Anexo III (Fator R ≥ 28%).
A13: Vermelho claro = Anexo V (Fator R < 28%).
A15: Cenários de pró-labore
... A26: • Brasília (DF): ISS está embutido no DAS do Simples neste modelo (como no seu documento).

Sheet Parâmetros
A1: Parâmetros editáveis
A3: EMPRESA / REGIME
A4: Alíquota Anexo III (Fator R ≥ 28%) | B4: 0.06 | C4: ← amarelo = editável
A5: Alíquota Anexo V (Fator R < 28%) | B5: 0.155
A6: Meta Fator R | B6: 0.28
A7: INSS pró-labore (%) | B7: 0.11
A8: Teto INSS 2026 | B8: 8157.41
A9: Desconto simplificado IRRF mensal | B9: 607.2
A10: Dedução por dependente (mensal) | B10: 189.59
A12: PESSOA FÍSICA / FAMÍLIA
A13: CLT bruto mensal (você) | B13: 10000
A14: Nº dependentes (filhos) | B14: 2
A15: Dependentes alocados no CLT? (1=sim, 0=não) | B15: 1
A16: Meses de CLT em 2026 (ex.: 5 se começou em ago) | B16: 5
A18: CENÁRIOS DE PRÓ-LABORE
A19: C1 — Pró-labore fixo atual | B19: 4400
A20: C2 — Modo (deixar AUTOMATICO) | B20: AUTOMATICO
A21: C3 — Pró-labore fixo alternativo | B21: 7300
A22: Pró-labore mínimo (piso, ex. salário mínimo) | B22: 1518
A23: C2 — Início do ajuste automático (mês) | B23: 46266 | C23: Antes disso, C2 usa o pró-labore atual (histórico real)
A24: TABELA IRRF 2026 (referência — usada nas fórmulas)
A25: Faixa 1 teto (isento) | B25: 2428.8
A26: Faixa 2 teto | B26: 2826.65
A27: Faixa 3 teto | B27: 3751.05
A28: Faixa 4 teto | B28: 4664.68
A29: Deduzir faixa 2 (7,5%) | B29: 182.16
A30: Deduzir faixa 3 (15%) | B30: 394.16
A31: Deduzir faixa 4 (22,5%) | B31: 675.49
A32: Deduzir faixa 5 (27,5%) | B32: 908.73
A33: Redução: isenção até | B33: 5000
A34: Redução: teto parcial | B34: 7350
A35: Redução: constante | B35: 978.62
A36: Redução: coeficiente | B36: 0.133145
A38: Named ranges usados pela Simulação:
A39: Os valores desta aba alimentam as fórmulas das outras abas. Não renomeie as células B4:B22.

Sheet Notas
A1: Notas fiscais por empresa (preencha os nomes e valores)
A2: Campos amarelos são editáveis. O total mensal alimenta a aba Simulação e o Fator R.
A3: Preencha os nomes na linha 5 (amarelo). Cada coluna é uma empresa contratante; some até 5. Se a nota for menor, só altere o valor do mês.
A4: Mês | B4: Empresa 1 | C4: Empresa 2 | D4: Empresa 3 | E4: Empresa 4 | F4: Empresa 5 | G4: Total do mês
A5: Nome da empresa → | B5: Contrato atual (editar) | C5: Contrato novo (editar) | G5: ← digite os nomes aqui
A6: 45658 | B6: 15500 | C6: 0 | D6: 0 | E6: 0 | F6: 0 | G6: =SUM(B6:F6)
A7: 45689 | B7: 15500 | C7: 0 | D7: 0 | E7: 0 | F7: 0 | G7: =SUM(B7:F7)
A8: 45717 | B8: 15500 | C8: 0 | D8: 0 | E8: 0 | F8: 0 | G8: =SUM(B8:F8)
A9: 45748 | B9: 15500 | C9: 0 | D9: 0 | E9: 0 | F9: 0 | G9: =SUM(B9:F9)
A10: 45778 | B10: 15500 | C10: 0 | D10: 0 | E10: 0 | F10: 0 | G10: =SUM(B10:F10)
A11: 45809 | B11: 15500 | C11: 0 | D11: 0 | E11: 0 | F11: 0 | G11: =SUM(B11:F11)
A12: 45839 | B12: 15500 | C12: 0 | D12: 0 | E12: 0 | F12: 0 | G12: =SUM(B12:F12)
A13: 45870 | B13: 15500 | C13: 0 | D13: 0 | E13: 0 | F13: 0 | G13: =SUM(B13:F13)
A14: 45901 | B14: 15500 | C14: 0 | D14: 0 | E14: 0 | F14: 0 | G14: =SUM(B14:F14)
A15: 45931 | B15: 15500 | C15: 0 | D15: 0 | E15: 0 | F15: 0 | G15: =SUM(B15:F15)
A16: 45962 | B16: 15500 | C16: 0 | D16: 0 | E16: 0 | F16: 0 | G16: =SUM(B16:F16)
A17: 45992 | B17: 15500 | C17: 0 | D17: 0 | E17: 0 | F17: 0 | G17: =SUM(B17:F17)
... A41: 46722 | B41: 15500 | C41: 10500 | D41: 0 | E41: 0 | F41: 0 | G41: =SUM(B41:F41)
A43: Dica: os valores já vêm pré-preenchidos com R$ 15.500 (empresa 1) e, a partir de set/2026, + R$ 10.500 (empresa 2). Ajuste se a nota for um pouco menor.

Sheet Simulação
A1: Simulação mês a mês — DAS, Fator R, pró-labore, INSS, IRRF, lucro e líquido familiar
A2: Receita vem da aba Notas. Altere o valor da nota lá e o Fator R / pró-labore sugerido atualizam aqui.
C3: CENÁRIO 1 — Pró-labore atual (fixo) | K3: CENÁRIO 2 — Automático (mínimo p/ Fator R ≥ meta) | S3: CENÁRIO 3 — Pró-labore manual alternativo
A4: Mês | B4: Receita | C4: Pró-labore | D4: Fator R | E4: Anexo | F4: DAS | G4: INSS | H4: IRRF | I4: Lucro isento* | J4: Líquido familiar** | K4: Pró-labore | L4: Fator R | M4: Anexo | N4: DAS | O4: INSS | P4: IRRF | Q4: Lucro isento* | R4: Líquido familiar** | S4: Pró-labore | T4: Fator R | U4: Anexo | V4: DAS | W4: INSS | X4: IRRF | Y4: Lucro isento* | Z4: Líquido familiar**
A5: 45658 | B5: =Notas!G6 | C5: =Parâmetros!$B$19 | D5: =IF(B5=0,0,C5/B5) | E5: =IF(D5>=Parâmetros!$B$6,"III","V") | F5: =IF(E5="III",B5*Parâmetros!$B$4,B5*Parâmetros!$B$5) | G5: =MIN(C5,Parâmetros!$B$8)*Parâmetros!$B$7 | H5: =IF(C5<=Parâmetros!$B$33,0,MAX(0,(IF(MAX(0,C5-(MIN(C5,Parâmetros!$B$8)*Parâmetros!$B$7)-(IF(Parâmetros!$B$15=1,0,Parâmetros!$B$14)*Parâmetros!$B$10))<=Parâmetros!$B$25,0,IF(MAX(0,C5-(MIN(C5,Parâmetros!$B$8)*Parâmetros!$B$7)-(IF(Parâmetros!$B$15=1,0,Parâmetros!$B$14)*Parâmetros!$B$10))<=Parâmetros!$B$26,MAX(0,C5-(MIN(C5,Parâmetros!$B$8)*Parâmetros!$B$7)-(IF(Parâmetros!$B$15=1,0,Parâmetros!$B$14)*Parâmetros!$B$10))*0.075-Parâmetros!$B$29,IF(MAX(0,C5-(MIN(C5,Parâmetros!$B$8)*Parâmetros!$B$7)-(IF(Parâmetros!$B$15=1,0,Parâmetros!$B$14)*Parâmetros!$B$10))<=Parâmetros!$B$27,MAX(0,C5-(MIN(C5,Parâmetros!$B$8)*Parâmetros!$B$7)-(IF(Parâmetros!$B$15=1,0,Parâmetros!$B$14)*Parâmetros!$B$10))*0.15-Parâmetros!$B$30,IF(MAX(0,C5-(MIN(C5,Parâmetros!$B$8)*Parâmetros!$B$7)-(IF(Parâmetros!$B$15=1,0,Parâmetros!$B$14)*Parâmetros!$B$10))<=Parâmetros!$B$28,MAX(0,C5-(MIN(C5,Parâmetros!$B$8)*Parâmetros!$B$7)-(IF(Parâmetros!$B$15=1,0,Parâmetros!$B$14)*Parâmetros!$B$10))*0.225-Parâmetros!$B$31,MAX(0,C5-(MIN(C5,Parâmetros!$B$8)*Parâmetros!$B$7)-(IF(Parâmetros!$B$15=1,0,Parâmetros!$B$14)*Parâmetros!$B$10))*0.275-Parâmetros!$B$32)))))-IF(C5<=Parâmetros!$B$34,Parâmetros!$B$35-Parâmetros!$B$36*C5,0))) | I5: =MAX(0,B5-F5-C5) | J5: =B5-F5-G5-H5 | K5: =IF(A5<Parâmetros!$B$23,Parâmetros!$B$19,MAX(Parâmetros!$B$22,Parâmetros!$B$6*B5)) | L5: =IF(B5=0,0,K5/B5) | M5: =IF(L5>=Parâmetros!$B$6,"III","V") | N5: =IF(M5="III",B5*Parâmetros!$B$4,B5*Parâmetros!$B$5) | O5: =MIN(K5,Parâmetros!$B$8)*Parâmetros!$B$7 | P5: =IF(K5<=Parâmetros!$B$33,0,MAX(0,(IF(MAX(0,K5-(MIN(K5,Parâmetros!$B$8)*Parâmetros!$B$7)-(IF(Parâmetros!$B$15=1,0,Parâmetros!$B$14)*Parâmetros!$B$10))<=Parâmetros!$B$25,0,IF(MAX(0,K5-(MIN(K5,Parâmetros!$B$8)*Parâmetros!$B$7)-(IF(Parâmetros!$B$15=1,0,Parâmetros!$B$14)*Parâmetros!$B$10))<=Parâmetros!$B$26,MAX(0,K5-(MIN(K5,Parâmetros!$B$8)*Parâmetros!$B$7)-(IF(Parâmetros!$B$15=1,0,Parâmetros!$B$14)*Parâmetros!$B$10))*0.075-Parâmetros!$B$29,IF(MAX(0,K5-(MIN(K5,Parâmetros!$B$8)*Parâmetros!$B$7)-(IF(Parâmetros!$B$15=1,0,Parâmetros!$B$14)*Parâmetros!$B$10))<=Parâmetros!$B$27,MAX(0,K5-(MIN(K5,Parâmetros!$B$8)*Parâmetros!$B$7)-(IF(Parâmetros!$B$15=1,0,Parâmetros!$B$14)*Parâmetros!$B$10))*0.15-Parâmetros!$B$30,IF(MAX(0,K5-(MIN(K5,Parâmetros!$B$8)*Parâmetros!$B$7)-(IF(Parâmetros!$B$15=1,0,Parâmetros!$B$14)*Parâmetros!$B$10))<=Parâmetros!$B$28,MAX(0,K5-(MIN(K5,Parâmetros!$B$8)*Parâmetros!$B$7)-(IF(Parâmetros!$B$15=1,0,Parâmetros!$B$14)*Parâmetros!$B$10))*0.225-Parâmetros!$B$31,MAX(0,K5-(MIN(K5,Parâmetros!$B$8)*Parâmetros!$B$7)-(IF(Parâmetros!$B$15=1,0,Parâmetros!$B$14)*Parâmetros!$B$10))*0.275-Parâmetros!$B$32)))))-IF(K5<=Parâmetros!$B$34,Parâmetros!$B$35-Parâmetros!$B$36*K5,0))) | Q5: =MAX(0,B5-N5-K5) | R5: =B5-N5-O5-P5 | S5: =Parâmetros!$B$21 | T5: =IF(B5=0,0,S5/B5) | U5: =IF(T5>=Parâmetros!$B$6,"III","V") | V5: =IF(U5="III",B5*Parâmetros!$B$4,B5*Parâmetros!$B$5) | W5: =MIN(S5,Parâmetros!$B$8)*Parâmetros!$B$7 | X5: =IF(S5<=Parâmetros!$B$33,0,MAX(0,(IF(MAX(0,S5-(MIN(S5,Parâmetros!$B$8)*Parâmetros!$B$7)-(IF(Parâmetros!$B$15=1,0,Parâmetros!$B$14)*Parâmetros!$B$10))<=Parâmetros!$B$25,0,IF(MAX(0,S5-(MIN(S5,Parâmetros!$B$8)*Parâmetros!$B$7)-(IF(Parâmetros!$B$15=1,0,Parâmetros!$B$14)*Parâmetros!$B$10))<=Parâmetros!$B$26,MAX(0,S5-(MIN(S5,Parâmetros!$B$8)*Parâmetros!$B$7)-(IF(Parâmetros!$B$15=1,0,Parâmetros!$B$14)*Parâmetros!$B$10))*0.075-Parâmetros!$B$29,IF(MAX(0,S5-(MIN(S5,Parâmetros!$B$8)*Parâmetros!$B$7)-(IF(Parâmetros!$B$15=1,0,Parâmetros!$B$14)*Parâmetros!$B$10))<=Parâmetros!$B$27,MAX(0,S5-(MIN(S5,Parâmetros!$B$8)*Parâmetros!$B$7)-(IF(Parâmetros!$B$15=1,0,Parâmetros!$B$14)*Parâmetros!$B$10))*0.15-Parâmetros!$B$30,IF(MAX(0,S5-(MIN(S5,Parâmetros!$B$8)*Parâmetros!$B$7)-(IF(Parâmetros!$B$15=1,0,Parâmetros!$B$14)*Parâmetros!$B$10))<=Parâmetros!$B$28,MAX(0,S5-(MIN(S5,Parâmetros!$B$8)*Parâmetros!$B$7)-(IF(Parâmetros!$B$15=1,0,Parâmetros!$B$14)*Parâmetros!$B$10))*0.225-Parâmetros!$B$31,MAX(0,S5-(MIN(S5,Parâmetros!$B$8)*Parâmetros!$B$7)-(IF(Parâmetros!$B$15=1,0,Parâmetros!$B$14)*Parâmetros!$B$10))*0.275-Parâmetros!$B$32)))))-IF(S5<=Parâmetros!$B$34,Parâmetros!$B$35-Parâmetros!$B$36*S5,0))) | Y5: =MAX(0,B5-V5-S5) | Z5: =B5-V5-W5-X5
A6: 45689 | B6: =Notas!G7 | C6: =Parâmetros!$B$19 | D6: =IF(SUM(B5:B6)=0,0,SUM(C5:C6)/SUM(B5:B6)) | E6: =IF(D6>=Parâmetros!$B$6,"III","V") | F6: =IF(E6="III",B6*Parâmetros!$B$4,B6*Parâmetros!$B$5) | G6: =MIN(C6,Parâmetros!$B$8)*Parâmetros!$B$7 | H6: =IF(C6<=Parâmetros!$B$33,0,MAX(0,(IF(MAX(0,C6-(MIN(C6,Parâmetros!$B$8)*Parâmetros!$B$7)-(IF(Parâmetros!$B$15=1,0,Parâmetros!$B$14)*Parâmetros!$B$10))<=Parâmetros!$B$25,0,IF(MAX(0,C6-(MIN(C6,Parâmetros!$B$8)*Parâmetros!$B$7)-(IF(Parâmetros!$B$15=1,0,Parâmetros!$B$14)*Parâmetros!$B$10))<=Parâmetros!$B$26,MAX(0,C6-(MIN(C6,Parâmetros!$B$8)*Parâmetros!$B$7)-(IF(Parâmetros!$B$15=1,0,Parâmetros!$B$14)*Parâmetros!$B$10))*0.075-Parâmetros!$B$29,IF(MAX(0,C6-(MIN(C6,Parâmetros!$B$8)*Parâmetros!$B$7)-(IF(Parâmetros!$B$15=1,0,Parâmetros!$B$14)*Parâmetros!$B$10))<=Parâmetros!$B$27,MAX(0,C6-(MIN(C6,Parâmetros!$B$8)*Parâmetros!$B$7)-(IF(Parâmetros!$B$15=1,0,Parâmetros!$B$14)*Parâmetros!$B$10))*0.15-Parâmetros!$B$30,IF(MAX(0,C6-(MIN(C6,Parâmetros!$B$8)*Parâmetros!$B$7)-(IF(Parâmetros!$B$15=1,0,Parâmetros!$B$14)*Parâmetros!$B$10))<=Parâmetros!$B$28,MAX(0,C6-(MIN(C6,Parâmetros!$B$8)*Parâmetros!$B$7)-(IF(Parâmetros!$B$15=1,0,Parâmetros!$B$14)*Parâmetros!$B$10))*0.225-Parâmetros!$B$31,MAX(0,C6-(MIN(C6,Parâmetros!$B$8)*Parâmetros!$B$7)-(IF(Parâmetros!$B$15=1,0,Parâmetros!$B$14)*Parâmetros!$B$10))*0.275-Parâmetros!$B$32)))))-IF(C6<=Parâmetros!$B$34,Parâmetros!$B$35-Parâmetros!$B$36*C6,0))) | I6: =MAX(0,B6-F6-C6) | J6: =B6-F6-G6-H6 | K6: =IF(A6<Parâmetros!$B$23,Parâmetros!$B$19,MAX(Parâmetros!$B$22,Parâmetros!$B$6*SUM(B5:B6)-SUM(K5:K5))) | L6: =IF(SUM(B5:B6)=0,0,SUM(K5:K6)/SUM(B5:B6)) | M6: =IF(L6>=Parâmetros!$B$6,"III","V") | N6: =IF(M6="III",B6*Parâmetros!$B$4,B6*Parâmetros!$B$5) | O6: =MIN(K6,Parâmetros!$B$8)*Parâmetros!$B$7 | P6: =IF(K6<=Parâmetros!$B$33,0,MAX(0,(IF(MAX(0,K6-(MIN(K6,Parâmetros!$B$8)*Parâmetros!$B$7)-(IF(Parâmetros!$B$15=1,0,Parâmetros!$B$14)*Parâmetros!$B$10))<=Parâmetros!$B$25,0,IF(MAX(0,K6-(MIN(K6,Parâmetros!$B$8)*Parâmetros!$B$7)-(IF(Parâmetros!$B$15=1,0,Parâmetros!$B$14)*Parâmetros!$B$10))<=Parâmetros!$B$26,MAX(0,K6-(MIN(K6,Parâmetros!$B$8)*Parâmetros!$B$7)-(IF(Parâmetros!$B$15=1,0,Parâmetros!$B$14)*Parâmetros!$B$10))*0.075-Parâmetros!$B$29,IF(MAX(0,K6-(MIN(K6,Parâmetros!$B$8)*Parâmetros!$B$7)-(IF(Parâmetros!$B$15=1,0,Parâmetros!$B$14)*Parâmetros!$B$10))<=Parâmetros!$B$27,MAX(0,K6-(MIN(K6,Parâmetros!$B$8)*Parâmetros!$B$7)-(IF(Parâmetros!$B$15=1,0,Parâmetros!$B$14)*Parâmetros!$B$10))*0.15-Parâmetros!$B$30,IF(MAX(0,K6-(MIN(K6,Parâmetros!$B$8)*Parâmetros!$B$7)-(IF(Parâmetros!$B$15=1,0,Parâmetros!$B$14)*Parâmetros!$B$10))<=Parâmetros!$B$28,MAX(0,K6-(MIN(K6,Parâmetros!$B$8)*Parâmetros!$B$7)-(IF(Parâmetros!$B$15=1,0,Parâmetros!$B$14)*Parâmetros!$B$10))*0.225-Parâmetros!$B$31,MAX(0,K6-(MIN(K6,Parâmetros!$B$8)*Parâmetros!$B$7)-(IF(Parâmetros!$B$15=1,0,Parâmetros!$B$14)*Parâmetros!$B$10))*0.275-Parâmetros!$B$32)))))-IF(K6<=Parâmetros!$B$34,Parâmetros!$B$35-Parâmetros!$B$36*K6,0))) | Q6: =MAX(0,B6-N6-K6) | R6: =B6-N6-O6-P6 | S6: =Parâmetros!$B$21 | T6: =IF(SUM(B5:B6)=0,0,SUM(S5:S6)/SUM(B5:B6)) | U6: =IF(T6>=Parâmetros!$B$6,"III","V") | V6: =IF(U6="III",B6*Parâmetros!$B$4,B6*Parâmetros!$B$5) | W6: =MIN(S6,Parâmetros!$B$8)*Parâmetros!$B$7 | X6: =IF(S6<=Parâmetros!$B$33,0,MAX(0,(IF(MAX(0,S6-(MIN(S6,Parâmetros!$B$8)*Parâmetros!$B$7)-(IF(Parâmetros!$B$15=1,0,Parâmetros!$B$14)*Parâmetros!$B$10))<=Parâmetros!$B$25,0,IF(MAX(0,S6-(MIN(S6,Parâmetros!$B$8)*Parâmetros!$B$7)-(IF(Parâmetros!$B$15=1,0,Parâmetros!$B$14)*Parâmetros!$B$10))<=Parâmetros!$B$26,MAX(0,S6-(MIN(S6,Parâmetros!$B$8)*Parâmetros!$B$7)-(IF(Parâmetros!$B$15=1,0,Parâmetros!$B$14)*Parâmetros!$B$10))*0.075-Parâmetros!$B$29,IF(MAX(0,S6-(MIN(S6,Parâmetros!$B$8)*Parâmetros!$B$7)-(IF(Parâmetros!$B$15=1,0,Parâmetros!$B$14)*Parâmetros!$B$10))<=Parâmetros!$B$27,MAX(0,S6-(MIN(S6,Parâmetros!$B$8)*Parâmetros!$B$7)-(IF(Parâmetros!$B$15=1,0,Parâmetros!$B$14)*Parâmetros!$B$10))*0.15-Parâmetros!$B$30,IF(MAX(0,S6-(MIN(S6,Parâmetros!$B$8)*Parâmetros!$B$7)-(IF(Parâmetros!$B$15=1,0,Parâmetros!$B$14)*Parâmetros!$B$10))<=Parâmetros!$B$28,MAX(0,S6-(MIN(S6,Parâmetros!$B$8)*Parâmetros!$B$7)-(IF(Parâmetros!$B$15=1,0,Parâmetros!$B$14)*Parâmetros!$B$10))*0.225-Parâmetros!$B$31,MAX(0,S6-(MIN(S6,Parâmetros!$B$8)*Parâmetros!$B$7)-(IF(Parâmetros!$B$15=1,0,Parâmetros!$B$14)*Parâmetros!$B$10))*0.275-Parâmetros!$B$32)))))-IF(S6<=Parâmetros!$B$34,Parâmetros!$B$35-Parâmetros!$B$36*S6,0))) | Y6: =MAX(0,B6-V6-S6) | Z6: =B6-V6-W6-X6
A7: 45717 | B7: =Notas!G8 | C7: =Parâmetros!$B$19 | D7: =IF(SUM(B5:B7)=0,0,SUM(C5:C7)/SUM(B5:B7)) | E7: =IF(D7>=Parâmetros!$B$6,"III","V") | F7: =IF(E7="III",B7*Parâmetros!$B$4,B7*Parâmetros!$B$5) | G7: =MIN(C7,Parâmetros!$B$8)*Parâmetros!$B$7 | H7: =IF(C7<=Parâmetros!$B$33,0,MAX(0,(IF(MAX(0,C7-(MIN(C7,Parâmetros!$B$8)*Parâmetros!$B$7)-(IF(Parâmetros!$B$15=1,0,Parâmetros!$B$14)*Parâmetros!$B$10))<=Parâmetros!$B$25,0,IF(MAX(0,C7-(MIN(C7,Parâmetros!$B$8)*Parâmetros!$B$7)-(IF(Parâmetros!$B$15=1,0,Parâmetros!$B$14)*Parâmetros!$B$10))<=Parâmetros!$B$26,MAX(0,C7-(MIN(C7,Parâmetros!$B$8)*Parâmetros!$B$7)-(IF(Parâmetros!$B$15=1,0,Parâmetros!$B$14)*Parâmetros!$B$10))*0.075-Parâmetros!$B$29,IF(MAX(0,C7-(MIN(C7,Parâmetros!$B$8)*Parâmetros!$B$7)-(IF(Parâmetros!$B$15=1,0,Parâmetros!$B$14)*Parâmetros!$B$10))<=Parâmetros!$B$27,MAX(0,C7-(MIN(C7,Parâmetros!$B$8)*Parâmetros!$B$7)-(IF(Parâmetros!$B$15=1,0,Parâmetros!$B$14)*Parâmetros!$B$10))*0.15-Parâmetros!$B$30,IF(MAX(0,C7-(MIN(C7,Parâmetros!$B$8)*Parâmetros!$B$7)-(IF(Parâmetros!$B$15=1,0,Parâmetros!$B$14)*Parâmetros!$B$10))<=Parâmetros!$B$28,MAX(0,C7-(MIN(C7,Parâmetros!$B$8)*Parâmetros!$B$7)-(IF(Parâmetros!$B$15=1,0,Parâmetros!$B$14)*Parâmetros!$B$10))*0.225-Parâmetros!$B$31,MAX(0,C7-(MIN(C7,Parâmetros!$B$8)*Parâmetros!$B$7)-(IF(Parâmetros!$B$15=1,0,Parâmetros!$B$14)*Parâmetros!$B$10))*0.275-Parâmetros!$B$32)))))-IF(C7<=Parâmetros!$B$34,Parâmetros!$B$35-Parâmetros!$B$36*C7,0))) | I7: =MAX(0,B7-F7-C7) | J7: =B7-F7-G7-H7 | K7: =IF(A7<Parâmetros!$B$23,Parâmetros!$B$19,MAX(Parâmetros!$B$22,Parâmetros!$B$6*SUM(B5:B7)-SUM(K5:K6))) | L7: =IF(SUM(B5:B7)=0,0,SUM(K5:K7)/SUM(B5:B7)) | M7: =IF(L7>=Parâmetros!$B$6,"III","V") | N7: =IF(M7="III",B7*Parâmetros!$B$4,B7*Parâmetros!$B$5) | O7: =MIN(K7,Parâmetros!$B$8)*Parâmetros!$B$7 | P7: =IF(K7<=Parâmetros!$B$33,0,MAX(0,(IF(MAX(0,K7-(MIN(K7,Parâmetros!$B$8)*Parâmetros!$B$7)-(IF(Parâmetros!$B$15=1,0,Parâmetros!$B$14)*Parâmetros!$B$10))<=Parâmetros!$B$25,0,IF(MAX(0,K7-(MIN(K7,Parâmetros!$B$8)*Parâmetros!$B$7)-(IF(Parâmetros!$B$15=1,0,Parâmetros!$B$14)*Parâmetros!$B$10))<=Parâmetros!$B$26,MAX(0,K7-(MIN(K7,Parâmetros!$B$8)*Parâmetros!$B$7)-(IF(Parâmetros!$B$15=1,0,Parâmetros!$B$14)*Parâmetros!$B$10))*0.075-Parâmetros!$B$29,IF(MAX(0,K7-(MIN(K7,Parâmetros!$B$8)*Parâmetros!$B$7)-(IF(Parâmetros!$B$15=1,0,Parâmetros!$B$14)*Parâmetros!$B$10))<=Parâmetros!$B$27,MAX(0,K7-(MIN(K7,Parâmetros!$B$8)*Parâmetros!$B$7)-(IF(Parâmetros!$B$15=1,0,Parâmetros!$B$14)*Parâmetros!$B$10))*0.15-Parâmetros!$B$30,IF(MAX(0,K7-(MIN(K7,Parâmetros!$B$8)*Parâmetros!$B$7)-(IF(Parâmetros!$B$15=1,0,Parâmetros!$B$14)*Parâmetros!$B$10))<=Parâmetros!$B$28,MAX(0,K7-(MIN(K7,Parâmetros!$B$8)*Parâmetros!$B$7)-(IF(Parâmetros!$B$15=1,0,Parâmetros!$B$14)*Parâmetros!$B$10))*0.225-Parâmetros!$B$31,MAX(0,K7-(MIN(K7,Parâmetros!$B$8)*Parâmetros!$B$7)-(IF(Parâmetros!$B$15=1,0,Parâmetros!$B$14)*Parâmetros!$B$10))*0.275-Parâmetros!$B$32)))))-IF(K7<=Parâmetros!$B$34,Parâmetros!$B$35-Parâmetros!$B$36*K7,0))) | Q7: =MAX(0,B7-N7-K7) | R7: =B7-N7-O7-P7 | S7: =Parâmetros!$B$21 | T7: =IF(SUM(B5:B7)=0,0,SUM(S5:S7)/SUM(B5:B7)) | U7: =IF(T7>=Parâmetros!$B$6,"III","V") | V7: =IF(U7="III",B7*Parâmetros!$B$4,B7*Parâmetros!$B$5) | W7: =MIN(S7,Parâmetros!$B$8)*Parâmetros!$B$7 | X7: =IF(S7<=Parâmetros!$B$33,0,MAX(0,(IF(MAX(0,S7-(MIN(S7,Parâmetros!$B$8)*Parâmetros!$B$7)-(IF(Parâmetros!$B$15=1,0,Parâmetros!$B$14)*Parâmetros!$B$10))<=Parâmetros!$B$25,0,IF(MAX(0,S7-(MIN(S7,Parâmetros!$B$8)*Parâmetros!$B$7)-(IF(Parâmetros!$B$15=1,0,Parâmetros!$B$14)*Parâmetros!$B$10))<=Parâmetros!$B$26,MAX(0,S7-(MIN(S7,Parâmetros!$B$8)*Parâmetros!$B$7)-(IF(Parâmetros!$B$15=1,0,Parâmetros!$B$14)*Parâmetros!$B$10))*0.075-Parâmetros!$B$29,IF(MAX(0,S7-(MIN(S7,Parâmetros!$B$8)*Parâmetros!$B$7)-(IF(Parâmetros!$B$15=1,0,Parâmetros!$B$14)*Parâmetros!$B$10))<=Parâmetros!$B$27,MAX(0,S7-(MIN(S7,Parâmetros!$B$8)*Parâmetros!$B$7)-(IF(Parâmetros!$B$15=1,0,Parâmetros!$B$14)*Parâmetros!$B$10))*0.15-Parâmetros!$B$30,IF(MAX(0,S7-(MIN(S7,Parâmetros!$B$8)*Parâmetros!$B$7)-(IF(Parâmetros!$B$15=1,0,Parâmetros!$B$14)*Parâmetros!$B$10))<=Parâmetros!$B$28,MAX(0,S7-(MIN(S7,Parâmetros!$B$8)*Parâmetros!$B$7)-(IF(Parâmetros!$B$15=1,0,Parâmetros!$B$14)*Parâmetros!$B$10))*0.225-Parâmetros!$B$31,MAX(0,S7-(MIN(S7,Parâmetros!$B$8)*Parâmetros!$B$7)-(IF(Parâmetros!$B$15=1,0,Parâmetros!$B$14)*Parâmetros!$B$10))*0.275-Parâmetros!$B$32)))))-IF(S7<=Parâmetros!$B$34,Parâmetros!$B$35-Parâmetros!$B$36*S7,0))) | Y7: =MAX(0,B7-V7-S7) | Z7: =B7-V7-W7-X7
A8: 45748 | B8: =Notas!G9 | C8: =Parâmetros!$B$19 | D8: =IF(SUM(B5:B8)=0,0,SUM(C5:C8)/SUM(B5:B8)) | E8: =IF(D8>=Parâmetros!$B$6,"III","V") | F8: =IF(E8="III",B8*Parâmetros!$B$4,B8*Parâmetros!$B$5) | G8: =MIN(C8,Parâmetros!$B$8)*Parâmetros!$B$7 | H8: =IF(C8<=Parâmetros!$B$33,0,MAX(0,(IF(MAX(0,C8-(MIN(C8,Parâmetros!$B$8)*Parâmetros!$B$7)-(IF(Parâmetros!$B$15=1,0,Parâmetros!$B$14)*Parâmetros!$B$10))<=Parâmetros!$B$25,0,IF(MAX(0,C8-(MIN(C8,Parâmetros!$B$8)*Parâmetros!$B$7)-(IF(Parâmetros!$B$15=1,0,Parâmetros!$B$14)*Parâmetros!$B$10))<=Parâmetros!$B$26,MAX(0,C8-(MIN(C8,Parâmetros!$B$8)*Parâmetros!$B$7)-(IF(Parâmetros!$B$15=1,0,Parâmetros!$B$14)*Parâmetros!$B$10))*0.075-Parâmetros!$B$29,IF(MAX(0,C8-(MIN(C8,Parâmetros!$B$8)*Parâmetros!$B$7)-(IF(Parâmetros!$B$15=1,0,Parâmetros!$B$14)*Parâmetros!$B$10))<=Parâmetros!$B$27,MAX(0,C8-(MIN(C8,Parâmetros!$B$8)*Parâmetros!$B$7)-(IF(Parâmetros!$B$15=1,0,Parâmetros!$B$14)*Parâmetros!$B$10))*0.15-Parâmetros!$B$30,IF(MAX(0,C8-(MIN(C8,Parâmetros!$B$8)*Parâmetros!$B$7)-(IF(Parâmetros!$B$15=1,0,Parâmetros!$B$14)*Parâmetros!$B$10))<=Parâmetros!$B$28,MAX(0,C8-(MIN(C8,Parâmetros!$B$8)*Parâmetros!$B$7)-(IF(Parâmetros!$B$15=1,0,Parâmetros!$B$14)*Parâmetros!$B$10))*0.225-Parâmetros!$B$31,MAX(0,C8-(MIN(C8,Parâmetros!$B$8)*Parâmetros!$B$7)-(IF(Parâmetros!$B$15=1,0,Parâmetros!$B$14)*Parâmetros!$B$10))*0.275-Parâmetros!$B$32)))))-IF(C8<=Parâmetros!$B$34,Parâmetros!$B$35-Parâmetros!$B$36*C8,0))) | I8: =MAX(0,B8-F8-C8) | J8: =B8-F8-G8-H8 | K8: =IF(A8<Parâmetros!$B$23,Parâmetros!$B$19,MAX(Parâmetros!$B$22,Parâmetros!$B$6*SUM(B5:B8)-SUM(K5:K7))) | L8: =IF(SUM(B5:B8)=0,0,SUM(K5:K8)/SUM(B5:B8)) | M8: =IF(L8>=Parâmetros!$B$6,"III","V") | N8: =IF(M8="III",B8*Parâmetros!$B$4,B8*Parâmetros!$B$5) | O8: =MIN(K8,Parâmetros!$B$8)*Parâmetros!$B$7 | P8: =IF(K8<=Parâmetros!$B$33,0,MAX(0,(IF(MAX(0,K8-(MIN(K8,Parâmetros!$B$8)*Parâmetros!$B$7)-(IF(Parâmetros!$B$15=1,0,Parâmetros!$B$14)*Parâmetros!$B$10))<=Parâmetros!$B$25,0,IF(MAX(0,K8-(MIN(K8,Parâmetros!$B$8)*Parâmetros!$B$7)-(IF(Parâmetros!$B$15=1,0,Parâmetros!$B$14)*Parâmetros!$B$10))<=Parâmetros!$B$26,MAX(0,K8-(MIN(K8,Parâmetros!$B$8)*Parâmetros!$B$7)-(IF(Parâmetros!$B$15=1,0,Parâmetros!$B$14)*Parâmetros!$B$10))*0.075-Parâmetros!$B$29,IF(MAX(0,K8-(MIN(K8,Parâmetros!$B$8)*Parâmetros!$B$7)-(IF(Parâmetros!$B$15=1,0,Parâmetros!$B$14)*Parâmetros!$B$10))<=Parâmetros!$B$27,MAX(0,K8-(MIN(K8,Parâmetros!$B$8)*Parâmetros!$B$7)-(IF(Parâmetros!$B$15=1,0,Parâmetros!$B$14)*Parâmetros!$B$10))*0.15-Parâmetros!$B$30,IF(MAX(0,K8-(MIN(K8,Parâmetros!$B$8)*Parâmetros!$B$7)-(IF(Parâmetros!$B$15=1,0,Parâmetros!$B$14)*Parâmetros!$B$10))<=Parâmetros!$B$28,MAX(0,K8-(MIN(K8,Parâmetros!$B$8)*Parâmetros!$B$7)-(IF(Parâmetros!$B$15=1,0,Parâmetros!$B$14)*Parâmetros!$B$10))*0.225-Parâmetros!$B$31,MAX(0,K8-(MIN(K8,Parâmetros!$B$8)*Parâmetros!$B$7)-(IF(Parâmetros!$B$15=1,0,Parâmetros!$B$14)*Parâmetros!$B$10))*0.275-Parâmetros!$B$32)))))-IF(K8<=Parâmetros!$B$34,Parâmetros!$B$35-Parâmetros!$B$36*K8,0))) | Q8: =MAX(0,B8-N8-K8) | R8: =B8-N8-O8-P8 | S8: =Parâmetros!$B$21 | T8: =IF(SUM(B5:B8)=0,0,SUM(S5:S8)/SUM(B5:B8)) | U8: =IF(T8>=Parâmetros!$B$6,"III","V") | V8: =IF(U8="III",B8*Parâmetros!$B$4,B8*Parâmetros!$B$5) | W8: =MIN(S8,Parâmetros!$B$8)*Parâmetros!$B$7 | X8: =IF(S8<=Parâmetros!$B$33,0,MAX(0,(IF(MAX(0,S8-(MIN(S8,Parâmetros!$B$8)*Parâmetros!$B$7)-(IF(Parâmetros!$B$15=1,0,Parâmetros!$B$14)*Parâmetros!$B$10))<=Parâmetros!$B$25,0,IF(MAX(0,S8-(MIN(S8,Parâmetros!$B$8)*Parâmetros!$B$7)-(IF(Parâmetros!$B$15=1,0,Parâmetros!$B$14)*Parâmetros!$B$10))<=Parâmetros!$B$26,MAX(0,S8-(MIN(S8,Parâmetros!$B$8)*Parâmetros!$B$7)-(IF(Parâmetros!$B$15=1,0,Parâmetros!$B$14)*Parâmetros!$B$10))*0.075-Parâmetros!$B$29,IF(MAX(0,S8-(MIN(S8,Parâmetros!$B$8)*Parâmetros!$B$7)-(IF(Parâmetros!$B$15=1,0,Parâmetros!$B$14)*Parâmetros!$B$10))<=Parâmetros!$B$27,MAX(0,S8-(MIN(S8,Parâmetros!$B$8)*Parâmetros!$B$7)-(IF(Parâmetros!$B$15=1,0,Parâmetros!$B$14)*Parâmetros!$B$10))*0.15-Parâmetros!$B$30,IF(MAX(0,S8-(MIN(S8,Parâmetros!$B$8)*Parâmetros!$B$7)-(IF(Parâmetros!$B$15=1,0,Parâmetros!$B$14)*Parâmetros!$B$10))<=Parâmetros!$B$28,MAX(0,S8-(MIN(S8,Parâmetros!$B$8)*Parâmetros!$B$7)-(IF(Parâmetros!$B$15=1,0,Parâmetros!$B$14)*Parâmetros!$B$10))*0.225-Parâmetros!$B$31,MAX(0,S8-(MIN(S8,Parâmetros!$B$8)*Parâmetros!$B$7)-(IF(Parâmetros!$B$15=1,0,Parâmetros!$B$14)*Parâmetros!$B$10))*0.275-Parâmetros!$B$32)))))-IF(S8<=Parâmetros!$B$34,Parâmetros!$B$35-Parâmetros!$B$36*S8,0))) | Y8: =MAX(0,B8-V8-S8) | Z8: =B8-V8-W8-X8
A9: 45778 | B9: =Notas!G10 | C9: =Parâmetros!$B$19 | D9: =IF(SUM(B5:B9)=0,0,SUM(C5:C9)/SUM(B5:B9)) | E9: =IF(D9>=Parâmetros!$B$6,"III","V") | F9: =IF(E9="III",B9*Parâmetros!$B$4,B9*Parâmetros!$B$5) | G9: =MIN(C9,Parâmetros!$B$8)*Parâmetros!$B$7 | H9: =IF(C9<=Parâmetros!$B$33,0,MAX(0,(IF(MAX(0,C9-(MIN(C9,Parâmetros!$B$8)*Parâmetros!$B$7)-(IF(Parâmetros!$B$15=1,0,Parâmetros!$B$14)*Parâmetros!$B$10))<=Parâmetros!$B$25,0,IF(MAX(0,C9-(MIN(C9,Parâmetros!$B$8)*Parâmetros!$B$7)-(IF(Parâmetros!$B$15=1,0,Parâmetros!$B$14)*Parâmetros!$B$10))<=Parâmetros!$B$26,MAX(0,C9-(MIN(C9,Parâmetros!$B$8)*Parâmetros!$B$7)-(IF(Parâmetros!$B$15=1,0,Parâmetros!$B$14)*Parâmetros!$B$10))*0.075-Parâmetros!$B$29,IF(MAX(0,C9-(MIN(C9,Parâmetros!$B$8)*Parâmetros!$B$7)-(IF(Parâmetros!$B$15=1,0,Parâmetros!$B$14)*Parâmetros!$B$10))<=Parâmetros!$B$27,MAX(0,C9-(MIN(C9,Parâmetros!$B$8)*Parâmetros!$B$7)-(IF(Parâmetros!$B$15=1,0,Parâmetros!$B$14)*Parâmetros!$B$10))*0.15-Parâmetros!$B$30,IF(MAX(0,C9-(MIN(C9,Parâmetros!$B$8)*Parâmetros!$B$7)-(IF(Parâmetros!$B$15=1,0,Parâmetros!$B$14)*Parâmetros!$B$10))<=Parâmetros!$B$28,MAX(0,C9-(MIN(C9,Parâmetros!$B$8)*Parâmetros!$B$7)-(IF(Parâmetros!$B$15=1,0,Parâmetros!$B$14)*Parâmetros!$B$10))*0.225-Parâmetros!$B$31,MAX(0,C9-(MIN(C9,Parâmetros!$B$8)*Parâmetros!$B$7)-(IF(Parâmetros!$B$15=1,0,Parâmetros!$B$14)*Parâmetros!$B$10))*0.275-Parâmetros!$B$32)))))-IF(C9<=Parâmetros!$B$34,Parâmetros!$B$35-Parâmetros!$B$36*C9,0))) | I9: =MAX(0,B9-F9-C9) | J9: =B9-F9-G9-H9 | K9: =IF(A9<Parâmetros!$B$23,Parâmetros!$B$19,MAX(Parâmetros!$B$22,Parâmetros!$B$6*SUM(B5:B9)-SUM(K5:K8))) | L9: =IF(SUM(B5:B9)=0,0,SUM(K5:K9)/SUM(B5:B9)) | M9: =IF(L9>=Parâmetros!$B$6,"III","V") | N9: =IF(M9="III",B9*Parâmetros!$B$4,B9*Parâmetros!$B$5) | O9: =MIN(K9,Parâmetros!$B$8)*Parâmetros!$B$7 | P9: =IF(K9<=Parâmetros!$B$33,0,MAX(0,(IF(MAX(0,K9-(MIN(K9,Parâmetros!$B$8)*Parâmetros!$B$7)-(IF(Parâmetros!$B$15=1,0,Parâmetros!$B$14)*Parâmetros!$B$10))<=Parâmetros!$B$25,0,IF(MAX(0,K9-(MIN(K9,Parâmetros!$B$8)*Parâmetros!$B$7)-(IF(Parâmetros!$B$15=1,0,Parâmetros!$B$14)*Parâmetros!$B$10))<=Parâmetros!$B$26,MAX(0,K9-(MIN(K9,Parâmetros!$B$8)*Parâmetros!$B$7)-(IF(Parâmetros!$B$15=1,0,Parâmetros!$B$14)*Parâmetros!$B$10))*0.075-Parâmetros!$B$29,IF(MAX(0,K9-(MIN(K9,Parâmetros!$B$8)*Parâmetros!$B$7)-(IF(Parâmetros!$B$15=1,0,Parâmetros!$B$14)*Parâmetros!$B$10))<=Parâmetros!$B$27,MAX(0,K9-(MIN(K9,Parâmetros!$B$8)*Parâmetros!$B$7)-(IF(Parâmetros!$B$15=1,0,Parâmetros!$B$14)*Parâmetros!$B$10))*0.15-Parâmetros!$B$30,IF(MAX(0,K9-(MIN(K9,Parâmetros!$B$8)*Parâmetros!$B$7)-(IF(Parâmetros!$B$15=1,0,Parâmetros!$B$14)*Parâmetros!$B$10))<=Parâmetros!$B$28,MAX(0,K9-(MIN(K9,Parâmetros!$B$8)*Parâmetros!$B$7)-(IF(Parâmetros!$B$15=1,0,Parâmetros!$B$14)*Parâmetros!$B$10))*0.225-Parâmetros!$B$31,MAX(0,K9-(MIN(K9,Parâmetros!$B$8)*Parâmetros!$B$7)-(IF(Parâmetros!$B$15=1,0,Parâmetros!$B$14)*Parâmetros!$B$10))*0.275-Parâmetros!$B$32)))))-IF(K9<=Parâmetros!$B$34,Parâmetros!$B$35-Parâmetros!$B$36*K9,0))) | Q9: =MAX(0,B9-N9-K9) | R9: =B9-N9-O9-P9 | S9: =Parâmetros!$B$21 | T9: =IF(SUM(B5:B9)=0,0,SUM(S5:S9)/SUM(B5:B9)) | U9: =IF(T9>=Parâmetros!$B$6,"III","V") | V9: =IF(U9="III",B9*Parâmetros!$B$4,B9*Parâmetros!$B$5) | W9: =MIN(S9,Parâmetros!$B$8)*Parâmetros!$B$7 | X9: =IF(S9<=Parâmetros!$B$33,0,MAX(0,(IF(MAX(0,S9-(MIN(S9,Parâmetros!$B$8)*Parâmetros!$B$7)-(IF(Parâmetros!$B$15=1,0,Parâmetros!$B$14)*Parâmetros!$B$10))<=Parâmetros!$B$25,0,IF(MAX(0,S9-(MIN(S9,Parâmetros!$B$8)*Parâmetros!$B$7)-(IF(Parâmetros!$B$15=1,0,Parâmetros!$B$14)*Parâmetros!$B$10))<=Parâmetros!$B$26,MAX(0,S9-(MIN(S9,Parâmetros!$B$8)*Parâmetros!$B$7)-(IF(Parâmetros!$B$15=1,0,Parâmetros!$B$14)*Parâmetros!$B$10))*0.075-Parâmetros!$B$29,IF(MAX(0,S9-(MIN(S9,Parâmetros!$B$8)*Parâmetros!$B$7)-(IF(Parâmetros!$B$15=1,0,Parâmetros!$B$14)*Parâmetros!$B$10))<=Parâmetros!$B$27,MAX(0,S9-(MIN(S9,Parâmetros!$B$8)*Parâmetros!$B$7)-(IF(Parâmetros!$B$15=1,0,Parâmetros!$B$14)*Parâmetros!$B$10))*0.15-Parâmetros!$B$30,IF(MAX(0,S9-(MIN(S9,Parâmetros!$B$8)*Parâmetros!$B$7)-(IF(Parâmetros!$B$15=1,0,Parâmetros!$B$14)*Parâmetros!$B$10))<=Parâmetros!$B$28,MAX(0,S9-(MIN(S9,Parâmetros!$B$8)*Parâmetros!$B$7)-(IF(Parâmetros!$B$15=1,0,Parâmetros!$B$14)*Parâmetros!$B$10))*0.225-Parâmetros!$B$31,MAX(0,S9-(MIN(S9,Parâmetros!$B$8)*Parâmetros!$B$7)-(IF(Parâmetros!$B$15=1,0,Parâmetros!$B$14)*Parâmetros!$B$10))*0.275-Parâmetros!$B$32)))))-IF(S9<=Parâmetros!$B$34,Parâmetros!$B$35-Parâmetros!$B$36*S9,0))) | Y9: =MAX(0,B9-V9-S9) | Z9: =B9-V9-W9-X9
A10: 45809 | B10: =Notas!G11 | C10: =Parâmetros!$B$19 | D10: =IF(SUM(B5:B10)=0,0,SUM(C5:C10)/SUM(B5:B10)) | E10: =IF(D10>=Parâmetros!$B$6,"III","V") | F10: =IF(E10="III",B10*Parâmetros!$B$4,B10*Parâmetros!$B$5) | G10: =MIN(C10,Parâmetros!$B$8)*Parâmetros!$B$7 | H10: =IF(C10<=Parâmetros!$B$33,0,MAX(0,(IF(MAX(0,C10-(MIN(C10,Parâmetros!$B$8)*Parâmetros!$B$7)-(IF(Parâmetros!$B$15=1,0,Parâmetros!$B$14)*Parâmetros!$B$10))<=Parâmetros!$B$25,0,IF(MAX(0,C10-(MIN(C10,Parâmetros!$B$8)*Parâmetros!$B$7)-(IF(Parâmetros!$B$15=1,0,Parâmetros!$B$14)*Parâmetros!$B$10))<=Parâmetros!$B$26,MAX(0,C10-(MIN(C10,Parâmetros!$B$8)*Parâmetros!$B$7)-(IF(Parâmetros!$B$15=1,0,Parâmetros!$B$14)*Parâmetros!$B$10))*0.075-Parâmetros!$B$29,IF(MAX(0,C10-(MIN(C10,Parâmetros!$B$8)*Parâmetros!$B$7)-(IF(Parâmetros!$B$15=1,0,Parâmetros!$B$14)*Parâmetros!$B$10))<=Parâmetros!$B$27,MAX(0,C10-(MIN(C10,Parâmetros!$B$8)*Parâmetros!$B$7)-(IF(Parâmetros!$B$15=1,0,Parâmetros!$B$14)*Parâmetros!$B$10))*0.15-Parâmetros!$B$30,IF(MAX(0,C10-(MIN(C10,Parâmetros!$B$8)*Parâmetros!$B$7)-(IF(Parâmetros!$B$15=1,0,Parâmetros!$B$14)*Parâmetros!$B$10))<=Parâmetros!$B$28,MAX(0,C10-(MIN(C10,Parâmetros!$B$8)*Parâmetros!$B$7)-(IF(Parâmetros!$B$15=1,0,Parâmetros!$B$14)*Parâmetros!$B$10))*0.225-Parâmetros!$B$31,MAX(0,C10-(MIN(C10,Parâmetros!$B$8)*Parâmetros!$B$7)-(IF(Parâmetros!$B$15=1,0,Parâmetros!$B$14)*Parâmetros!$B$10))*0.275-Parâmetros!$B$32)))))-IF(C10<=Parâmetros!$B$34,Parâmetros!$B$35-Parâmetros!$B$36*C10,0))) | I10: =MAX(0,B10-F10-C10) | J10: =B10-F10-G10-H10 | K10: =IF(A10<Parâmetros!$B$23,Parâmetros!$B$19,MAX(Parâmetros!$B$22,Parâmetros!$B$6*SUM(B5:B10)-SUM(K5:K9))) | L10: =IF(SUM(B5:B10)=0,0,SUM(K5:K10)/SUM(B5:B10)) | M10: =IF(L10>=Parâmetros!$B$6,"III","V") | N10: =IF(M10="III",B10*Parâmetros!$B$4,B10*Parâmetros!$B$5) | O10: =MIN(K10,Parâmetros!$B$8)*Parâmetros!$B$7 | P10: =IF(K10<=Parâmetros!$B$33,0,MAX(0,(IF(MAX(0,K10-(MIN(K10,Parâmetros!$B$8)*Parâmetros!$B$7)-(IF(Parâmetros!$B$15=1,0,Parâmetros!$B$14)*Parâmetros!$B$10))<=Parâmetros!$B$25,0,IF(MAX(0,K10-(MIN(K10,Parâmetros!$B$8)*Parâmetros!$B$7)-(IF(Parâmetros!$B$15=1,0,Parâmetros!$B$14)*Parâmetros!$B$10))<=Parâmetros!$B$26,MAX(0,K10-(MIN(K10,Parâmetros!$B$8)*Parâmetros!$B$7)-(IF(Parâmetros!$B$15=1,0,Parâmetros!$B$14)*Parâmetros!$B$10))*0.075-Parâmetros!$B$29,IF(MAX(0,K10-(MIN(K10,Parâmetros!$B$8)*Parâmetros!$B$7)-(IF(Parâmetros!$B$15=1,0,Parâmetros!$B$14)*Parâmetros!$B$10))<=Parâmetros!$B$27,MAX(0,K10-(MIN(K10,Parâmetros!$B$8)*Parâmetros!$B$7)-(IF(Parâmetros!$B$15=1,0,Parâmetros!$B$14)*Parâmetros!$B$10))*0.15-Parâmetros!$B$30,IF(MAX(0,K10-(MIN(K10,Parâmetros!$B$8)*Parâmetros!$B$7)-(IF(Parâmetros!$B$15=1,0,Parâmetros!$B$14)*Parâmetros!$B$10))<=Parâmetros!$B$28,MAX(0,K10-(MIN(K10,Parâmetros!$B$8)*Parâmetros!$B$7)-(IF(Parâmetros!$B$15=1,0,Parâmetros!$B$14)*Parâmetros!$B$10))*0.225-Parâmetros!$B$31,MAX(0,K10-(MIN(K10,Parâmetros!$B$8)*Parâmetros!$B$7)-(IF(Parâmetros!$B$15=1,0,Parâmetros!$B$14)*Parâmetros!$B$10))*0.275-Parâmetros!$B$32)))))-IF(K10<=Parâmetros!$B$34,Parâmetros!$B$35-Parâmetros!$B$36*K10,0))) | Q10: =MAX(0,B10-N10-K10) | R10: =B10-N10-O10-P10 | S10: =Parâmetros!$B$21 | T10: =IF(SUM(B5:B10)=0,0,SUM(S5:S10)/SUM(B5:B10)) | U10: =IF(T10>=Parâmetros!$B$6,"III","V") | V10: =IF(U10="III",B10*Parâmetros!$B$4,B10*Parâmetros!$B$5) | W10: =MIN(S10,Parâmetros!$B$8)*Parâmetros!$B$7 | X10: =IF(S10<=Parâmetros!$B$33,0,MAX(0,(IF(MAX(0,S10-(MIN(S10,Parâmetros!$B$8)*Parâmetros!$B$7)-(IF(Parâmetros!$B$15=1,0,Parâmetros!$B$14)*Parâmetros!$B$10))<=Parâmetros!$B$25,0,IF(MAX(0,S10-(MIN(S10,Parâmetros!$B$8)*Parâmetros!$B$7)-(IF(Parâmetros!$B$15=1,0,Parâmetros!$B$14)*Parâmetros!$B$10))<=Parâmetros!$B$26,MAX(0,S10-(MIN(S10,Parâmetros!$B$8)*Parâmetros!$B$7)-(IF(Parâmetros!$B$15=1,0,Parâmetros!$B$14)*Parâmetros!$B$10))*0.075-Parâmetros!$B$29,IF(MAX(0,S10-(MIN(S10,Parâmetros!$B$8)*Parâmetros!$B$7)-(IF(Parâmetros!$B$15=1,0,Parâmetros!$B$14)*Parâmetros!$B$10))<=Parâmetros!$B$27,MAX(0,S10-(MIN(S10,Parâmetros!$B$8)*Parâmetros!$B$7)-(IF(Parâmetros!$B$15=1,0,Parâmetros!$B$14)*Parâmetros!$B$10))*0.15-Parâmetros!$B$30,IF(MAX(0,S10-(MIN(S10,Parâmetros!$B$8)*Parâmetros!$B$7)-(IF(Parâmetros!$B$15=1,0,Parâmetros!$B$14)*Parâmetros!$B$10))<=Parâmetros!$B$28,MAX(0,S10-(MIN(S10,Parâmetros!$B$8)*Parâmetros!$B$7)-(IF(Parâmetros!$B$15=1,0,Parâmetros!$B$14)*Parâmetros!$B$10))*0.225-Parâmetros!$B$31,MAX(0,S10-(MIN(S10,Parâmetros!$B$8)*Parâmetros!$B$7)-(IF(Parâmetros!$B$15=1,0,Parâmetros!$B$14)*Parâmetros!$B$10))*0.275-Parâmetros!$B$32)))))-IF(S10<=Parâmetros!$B$34,Parâmetros!$B$35-Parâmetros!$B$36*S10,0))) | Y10: =MAX(0,B10-V10-S10) | Z10: =B10-V10-W10-X10
A11: 45839 | B11: =Notas!G12 | C11: =Parâmetros!$B$19 | D11: =IF(SUM(B5:B11)=0,0,SUM(C5:C11)/SUM(B5:B11)) | E11: =IF(D11>=Parâmetros!$B$6,"III","V") | F11: =IF(E11="III",B11*Parâmetros!$B$4,B11*Parâmetros!$B$5) | G11: =MIN(C11,Parâmetros!$B$8)*Parâmetros!$B$7 | H11: =IF(C11<=Parâmetros!$B$33,0,MAX(0,(IF(MAX(0,C11-(MIN(C11,Parâmetros!$B$8)*Parâmetros!$B$7)-(IF(Parâmetros!$B$15=1,0,Parâmetros!$B$14)*Parâmetros!$B$10))<=Parâmetros!$B$25,0,IF(MAX(0,C11-(MIN(C11,Parâmetros!$B$8)*Parâmetros!$B$7)-(IF(Parâmetros!$B$15=1,0,Parâmetros!$B$14)*Parâmetros!$B$10))<=Parâmetros!$B$26,MAX(0,C11-(MIN(C11,Parâmetros!$B$8)*Parâmetros!$B$7)-(IF(Parâmetros!$B$15=1,0,Parâmetros!$B$14)*Parâmetros!$B$10))*0.075-Parâmetros!$B$29,IF(MAX(0,C11-(MIN(C11,Parâmetros!$B$8)*Parâmetros!$B$7)-(IF(Parâmetros!$B$15=1,0,Parâmetros!$B$14)*Parâmetros!$B$10))<=Parâmetros!$B$27,MAX(0,C11-(MIN(C11,Parâmetros!$B$8)*Parâmetros!$B$7)-(IF(Parâmetros!$B$15=1,0,Parâmetros!$B$14)*Parâmetros!$B$10))*0.15-Parâmetros!$B$30,IF(MAX(0,C11-(MIN(C11,Parâmetros!$B$8)*Parâmetros!$B$7)-(IF(Parâmetros!$B$15=1,0,Parâmetros!$B$14)*Parâmetros!$B$10))<=Parâmetros!$B$28,MAX(0,C11-(MIN(C11,Parâmetros!$B$8)*Parâmetros!$B$7)-(IF(Parâmetros!$B$15=1,0,Parâmetros!$B$14)*Parâmetros!$B$10))*0.225-Parâmetros!$B$31,MAX(0,C11-(MIN(C11,Parâmetros!$B$8)*Parâmetros!$B$7)-(IF(Parâmetros!$B$15=1,0,Parâmetros!$B$14)*Parâmetros!$B$10))*0.275-Parâmetros!$B$32)))))-IF(C11<=Parâmetros!$B$34,Parâmetros!$B$35-Parâmetros!$B$36*C11,0))) | I11: =MAX(0,B11-F11-C11) | J11: =B11-F11-G11-H11 | K11: =IF(A11<Parâmetros!$B$23,Parâmetros!$B$19,MAX(Parâmetros!$B$22,Parâmetros!$B$6*SUM(B5:B11)-SUM(K5:K10))) | L11: =IF(SUM(B5:B11)=0,0,SUM(K5:K11)/SUM(B5:B11)) | M11: =IF(L11>=Parâmetros!$B$6,"III","V") | N11: =IF(M11="III",B11*Parâmetros!$B$4,B11*Parâmetros!$B$5) | O11: =MIN(K11,Parâmetros!$B$8)*Parâmetros!$B$7 | P11: =IF(K11<=Parâmetros!$B$33,0,MAX(0,(IF(MAX(0,K11-(MIN(K11,Parâmetros!$B$8)*Parâmetros!$B$7)-(IF(Parâmetros!$B$15=1,0,Parâmetros!$B$14)*Parâmetros!$B$10))<=Parâmetros!$B$25,0,IF(MAX(0,K11-(MIN(K11,Parâmetros!$B$8)*Parâmetros!$B$7)-(IF(Parâmetros!$B$15=1,0,Parâmetros!$B$14)*Parâmetros!$B$10))<=Parâmetros!$B$26,MAX(0,K11-(MIN(K11,Parâmetros!$B$8)*Parâmetros!$B$7)-(IF(Parâmetros!$B$15=1,0,Parâmetros!$B$14)*Parâmetros!$B$10))*0.075-Parâmetros!$B$29,IF(MAX(0,K11-(MIN(K11,Parâmetros!$B$8)*Parâmetros!$B$7)-(IF(Parâmetros!$B$15=1,0,Parâmetros!$B$14)*Parâmetros!$B$10))<=Parâmetros!$B$27,MAX(0,K11-(MIN(K11,Parâmetros!$B$8)*Parâmetros!$B$7)-(IF(Parâmetros!$B$15=1,0,Parâmetros!$B$14)*Parâmetros!$B$10))*0.15-Parâmetros!$B$30,IF(MAX(0,K11-(MIN(K11,Parâmetros!$B$8)*Parâmetros!$B$7)-(IF(Parâmetros!$B$15=1,0,Parâmetros!$B$14)*Parâmetros!$B$10))<=Parâmetros!$B$28,MAX(0,K11-(MIN(K11,Parâmetros!$B$8)*Parâmetros!$B$7)-(IF(Parâmetros!$B$15=1,0,Parâmetros!$B$14)*Parâmetros!$B$10))*0.225-Parâmetros!$B$31,MAX(0,K11-(MIN(K11,Parâmetros!$B$8)*Parâmetros!$B$7)-(IF(Parâmetros!$B$15=1,0,Parâmetros!$B$14)*Parâmetros!$B$10))*0.275-Parâmetros!$B$32)))))-IF(K11<=Parâmetros!$B$34,Parâmetros!$B$35-Parâmetros!$B$36*K11,0))) | Q11: =MAX(0,B11-N11-K11) | R11: =B11-N11-O11-P11 | S11: =Parâmetros!$B$21 | T11: =IF(SUM(B5:B11)=0,0,SUM(S5:S11)/SUM(B5:B11)) | U11: =IF(T11>=Parâmetros!$B$6,"III","V") | V11: =IF(U11="III",B11*Parâmetros!$B$4,B11*Parâmetros!$B$5) | W11: =MIN(S11,Parâmetros!$B$8)*Parâmetros!$B$7 | X11: =IF(S11<=Parâmetros!$B$33,0,MAX(0,(IF(MAX(0,S11-(MIN(S11,Parâmetros!$B$8)*Parâmetros!$B$7)-(IF(Parâmetros!$B$15=1,0,Parâmetros!$B$14)*Parâmetros!$B$10))<=Parâmetros!$B$25,0,IF(MAX(0,S11-(MIN(S11,Parâmetros!$B$8)*Parâmetros!$B$7)-(IF(Parâmetros!$B$15=1,0,Parâmetros!$B$14)*Parâmetros!$B$10))<=Parâmetros!$B$26,MAX(0,S11-(MIN(S11,Parâmetros!$B$8)*Parâmetros!$B$7)-(IF(Parâmetros!$B$15=1,0,Parâmetros!$B$14)*Parâmetros!$B$10))*0.075-Parâmetros!$B$29,IF(MAX(0,S11-(MIN(S11,Parâmetros!$B$8)*Parâmetros!$B$7)-(IF(Parâmetros!$B$15=1,0,Parâmetros!$B$14)*Parâmetros!$B$10))<=Parâmetros!$B$27,MAX(0,S11-(MIN(S11,Parâmetros!$B$8)*Parâmetros!$B$7)-(IF(Parâmetros!$B$15=1,0,Parâmetros!$B$14)*Parâmetros!$B$10))*0.15-Parâmetros!$B$30,IF(MAX(0,S11-(MIN(S11,Parâmetros!$B$8)*Parâmetros!$B$7)-(IF(Parâmetros!$B$15=1,0,Parâmetros!$B$14)*Parâmetros!$B$10))<=Parâmetros!$B$28,MAX(0,S11-(MIN(S11,Parâmetros!$B$8)*Parâmetros!$B$7)-(IF(Parâmetros!$B$15=1,0,Parâmetros!$B$14)*Parâmetros!$B$10))*0.225-Parâmetros!$B$31,MAX(0,S11-(MIN(S11,Parâmetros!$B$8)*Parâmetros!$B$7)-(IF(Parâmetros!$B$15=1,0,Parâmetros!$B$14)*Parâmetros!$B$10))*0.275-Parâmetros!$B$32)))))-IF(S11<=Parâmetros!$B$34,Parâmetros!$B$35-Parâmetros!$B$36*S11,0))) | Y11: =MAX(0,B11-V11-S11) | Z11: =B11-V11-W11-X11
A12: 45870 | B12: =Notas!G13 | C12: =Parâmetros!$B$19 | D12: =IF(SUM(B5:B12)=0,0,SUM(C5:C12)/SUM(B5:B12)) | E12: =IF(D12>=Parâmetros!$B$6,"III","V") | F12: =IF(E12="III",B12*Parâmetros!$B$4,B12*Parâmetros!$B$5) | G12: =MIN(C12,Parâmetros!$B$8)*Parâmetros!$B$7 | H12: =IF(C12<=Parâmetros!$B$33,0,MAX(0,(IF(MAX(0,C12-(MIN(C12,Parâmetros!$B$8)*Parâmetros!$B$7)-(IF(Parâmetros!$B$15=1,0,Parâmetros!$B$14)*Parâmetros!$B$10))<=Parâmetros!$B$25,0,IF(MAX(0,C12-(MIN(C12,Parâmetros!$B$8)*Parâmetros!$B$7)-(IF(Parâmetros!$B$15=1,0,Parâmetros!$B$14)*Parâmetros!$B$10))<=Parâmetros!$B$26,MAX(0,C12-(MIN(C12,Parâmetros!$B$8)*Parâmetros!$B$7)-(IF(Parâmetros!$B$15=1,0,Parâmetros!$B$14)*Parâmetros!$B$10))*0.075-Parâmetros!$B$29,IF(MAX(0,C12-(MIN(C12,Parâmetros!$B$8)*Parâmetros!$B$7)-(IF(Parâmetros!$B$15=1,0,Parâmetros!$B$14)*Parâmetros!$B$10))<=Parâmetros!$B$27,MAX(0,C12-(MIN(C12,Parâmetros!$B$8)*Parâmetros!$B$7)-(IF(Parâmetros!$B$15=1,0,Parâmetros!$B$14)*Parâmetros!$B$10))*0.15-Parâmetros!$B$30,IF(MAX(0,C12-(MIN(C12,Parâmetros!$B$8)*Parâmetros!$B$7)-(IF(Parâmetros!$B$15=1,0,Parâmetros!$B$14)*Parâmetros!$B$10))<=Parâmetros!$B$28,MAX(0,C12-(MIN(C12,Parâmetros!$B$8)*Parâmetros!$B$7)-(IF(Parâmetros!$B$15=1,0,Parâmetros!$B$14)*Parâmetros!$B$10))*0.225-Parâmetros!$B$31,MAX(0,C12-(MIN(C12,Parâmetros!$B$8)*Parâmetros!$B$7)-(IF(Parâmetros!$B$15=1,0,Parâmetros!$B$14)*Parâmetros!$B$10))*0.275-Parâmetros!$B$32)))))-IF(C12<=Parâmetros!$B$34,Parâmetros!$B$35-Parâmetros!$B$36*C12,0))) | I12: =MAX(0,B12-F12-C12) | J12: =B12-F12-G12-H12 | K12: =IF(A12<Parâmetros!$B$23,Parâmetros!$B$19,MAX(Parâmetros!$B$22,Parâmetros!$B$6*SUM(B5:B12)-SUM(K5:K11))) | L12: =IF(SUM(B5:B12)=0,0,SUM(K5:K12)/SUM(B5:B12)) | M12: =IF(L12>=Parâmetros!$B$6,"III","V") | N12: =IF(M12="III",B12*Parâmetros!$B$4,B12*Parâmetros!$B$5) | O12: =MIN(K12,Parâmetros!$B$8)*Parâmetros!$B$7 | P12: =IF(K12<=Parâmetros!$B$33,0,MAX(0,(IF(MAX(0,K12-(MIN(K12,Parâmetros!$B$8)*Parâmetros!$B$7)-(IF(Parâmetros!$B$15=1,0,Parâmetros!$B$14)*Parâmetros!$B$10))<=Parâmetros!$B$25,0,IF(MAX(0,K12-(MIN(K12,Parâmetros!$B$8)*Parâmetros!$B$7)-(IF(Parâmetros!$B$15=1,0,Parâmetros!$B$14)*Parâmetros!$B$10))<=Parâmetros!$B$26,MAX(0,K12-(MIN(K12,Parâmetros!$B$8)*Parâmetros!$B$7)-(IF(Parâmetros!$B$15=1,0,Parâmetros!$B$14)*Parâmetros!$B$10))*0.075-Parâmetros!$B$29,IF(MAX(0,K12-(MIN(K12,Parâmetros!$B$8)*Parâmetros!$B$7)-(IF(Parâmetros!$B$15=1,0,Parâmetros!$B$14)*Parâmetros!$B$10))<=Parâmetros!$B$27,MAX(0,K12-(MIN(K12,Parâmetros!$B$8)*Parâmetros!$B$7)-(IF(Parâmetros!$B$15=1,0,Parâmetros!$B$14)*Parâmetros!$B$10))*0.15-Parâmetros!$B$30,IF(MAX(0,K12-(MIN(K12,Parâmetros!$B$8)*Parâmetros!$B$7)-(IF(Parâmetros!$B$15=1,0,Parâmetros!$B$14)*Parâmetros!$B$10))<=Parâmetros!$B$28,MAX(0,K12-(MIN(K12,Parâmetros!$B$8)*Parâmetros!$B$7)-(IF(Parâmetros!$B$15=1,0,Parâmetros!$B$14)*Parâmetros!$B$10))*0.225-Parâmetros!$B$31,MAX(0,K12-(MIN(K12,Parâmetros!$B$8)*Parâmetros!$B$7)-(IF(Parâmetros!$B$15=1,0,Parâmetros!$B$14)*Parâmetros!$B$10))*0.275-Parâmetros!$B$32)))))-IF(K12<=Parâmetros!$B$34,Parâmetros!$B$35-Parâmetros!$B$36*K12,0))) | Q12: =MAX(0,B12-N12-K12) | R12: =B12-N12-O12-P12 | S12: =Parâmetros!$B$21 | T12: =IF(SUM(B5:B12)=0,0,SUM(S5:S12)/SUM(B5:B12)) | U12: =IF(T12>=Parâmetros!$B$6,"III","V") | V12: =IF(U12="III",B12*Parâmetros!$B$4,B12*Parâmetros!$B$5) | W12: =MIN(S12,Parâmetros!$B$8)*Parâmetros!$B$7 | X12: =IF(S12<=Parâmetros!$B$33,0,MAX(0,(IF(MAX(0,S12-(MIN(S12,Parâmetros!$B$8)*Parâmetros!$B$7)-(IF(Parâmetros!$B$15=1,0,Parâmetros!$B$14)*Parâmetros!$B$10))<=Parâmetros!$B$25,0,IF(MAX(0,S12-(MIN(S12,Parâmetros!$B$8)*Parâmetros!$B$7)-(IF(Parâmetros!$B$15=1,0,Parâmetros!$B$14)*Parâmetros!$B$10))<=Parâmetros!$B$26,MAX(0,S12-(MIN(S12,Parâmetros!$B$8)*Parâmetros!$B$7)-(IF(Parâmetros!$B$15=1,0,Parâmetros!$B$14)*Parâmetros!$B$10))*0.075-Parâmetros!$B$29,IF(MAX(0,S12-(MIN(S12,Parâmetros!$B$8)*Parâmetros!$B$7)-(IF(Parâmetros!$B$15=1,0,Parâmetros!$B$14)*Parâmetros!$B$10))<=Parâmetros!$B$27,MAX(0,S12-(MIN(S12,Parâmetros!$B$8)*Parâmetros!$B$7)-(IF(Parâmetros!$B$15=1,0,Parâmetros!$B$14)*Parâmetros!$B$10))*0.15-Parâmetros!$B$30,IF(MAX(0,S12-(MIN(S12,Parâmetros!$B$8)*Parâmetros!$B$7)-(IF(Parâmetros!$B$15=1,0,Parâmetros!$B$14)*Parâmetros!$B$10))<=Parâmetros!$B$28,MAX(0,S12-(MIN(S12,Parâmetros!$B$8)*Parâmetros!$B$7)-(IF(Parâmetros!$B$15=1,0,Parâmetros!$B$14)*Parâmetros!$B$10))*0.225-Parâmetros!$B$31,MAX(0,S12-(MIN(S12,Parâmetros!$B$8)*Parâmetros!$B$7)-(IF(Parâmetros!$B$15=1,0,Parâmetros!$B$14)*Parâmetros!$B$10))*0.275-Parâmetros!$B$32)))))-IF(S12<=Parâmetros!$B$34,Parâmetros!$B$35-Parâmetros!$B$36*S12,0))) | Y12: =MAX(0,B12-V12-S12) | Z12: =B12-V12-W12-X12
A13: 45901 | B13: =Notas!G14 | C13: =Parâmetros!$B$19 | D13: =IF(SUM(B5:B13)=0,0,SUM(C5:C13)/SUM(B5:B13)) | E13: =IF(D13>=Parâmetros!$B$6,"III","V") | F13: =IF(E13="III",B13*Parâmetros!$B$4,B13*Parâmetros!$B$5) | G13: =MIN(C13,Parâmetros!$B$8)*Parâmetros!$B$7 | H13: =IF(C13<=Parâmetros!$B$33,0,MAX(0,(IF(MAX(0,C13-(MIN(C13,Parâmetros!$B$8)*Parâmetros!$B$7)-(IF(Parâmetros!$B$15=1,0,Parâmetros!$B$14)*Parâmetros!$B$10))<=Parâmetros!$B$25,0,IF(MAX(0,C13-(MIN(C13,Parâmetros!$B$8)*Parâmetros!$B$7)-(IF(Parâmetros!$B$15=1,0,Parâmetros!$B$14)*Parâmetros!$B$10))<=Parâmetros!$B$26,MAX(0,C13-(MIN(C13,Parâmetros!$B$8)*Parâmetros!$B$7)-(IF(Parâmetros!$B$15=1,0,Parâmetros!$B$14)*Parâmetros!$B$10))*0.075-Parâmetros!$B$29,IF(MAX(0,C13-(MIN(C13,Parâmetros!$B$8)*Parâmetros!$B$7)-(IF(Parâmetros!$B$15=1,0,Parâmetros!$B$14)*Parâmetros!$B$10))<=Parâmetros!$B$27,MAX(0,C13-(MIN(C13,Parâmetros!$B$8)*Parâmetros!$B$7)-(IF(Parâmetros!$B$15=1,0,Parâmetros!$B$14)*Parâmetros!$B$10))*0.15-Parâmetros!$B$30,IF(MAX(0,C13-(MIN(C13,Parâmetros!$B$8)*Parâmetros!$B$7)-(IF(Parâmetros!$B$15=1,0,Parâmetros!$B$14)*Parâmetros!$B$10))<=Parâmetros!$B$28,MAX(0,C13-(MIN(C13,Parâmetros!$B$8)*Parâmetros!$B$7)-(IF(Parâmetros!$B$15=1,0,Parâmetros!$B$14)*Parâmetros!$B$10))*0.225-Parâmetros!$B$31,MAX(0,C13-(MIN(C13,Parâmetros!$B$8)*Parâmetros!$B$7)-(IF(Parâmetros!$B$15=1,0,Parâmetros!$B$14)*Parâmetros!$B$10))*0.275-Parâmetros!$B$32)))))-IF(C13<=Parâmetros!$B$34,Parâmetros!$B$35-Parâmetros!$B$36*C13,0))) | I13: =MAX(0,B13-F13-C13) | J13: =B13-F13-G13-H13 | K13: =IF(A13<Parâmetros!$B$23,Parâmetros!$B$19,MAX(Parâmetros!$B$22,Parâmetros!$B$6*SUM(B5:B13)-SUM(K5:K12))) | L13: =IF(SUM(B5:B13)=0,0,SUM(K5:K13)/SUM(B5:B13)) | M13: =IF(L13>=Parâmetros!$B$6,"III","V") | N13: =IF(M13="III",B13*Parâmetros!$B$4,B13*Parâmetros!$B$5) | O13: =MIN(K13,Parâmetros!$B$8)*Parâmetros!$B$7 | P13: =IF(K13<=Parâmetros!$B$33,0,MAX(0,(IF(MAX(0,K13-(MIN(K13,Parâmetros!$B$8)*Parâmetros!$B$7)-(IF(Parâmetros!$B$15=1,0,Parâmetros!$B$14)*Parâmetros!$B$10))<=Parâmetros!$B$25,0,IF(MAX(0,K13-(MIN(K13,Parâmetros!$B$8)*Parâmetros!$B$7)-(IF(Parâmetros!$B$15=1,0,Parâmetros!$B$14)*Parâmetros!$B$10))<=Parâmetros!$B$26,MAX(0,K13-(MIN(K13,Parâmetros!$B$8)*Parâmetros!$B$7)-(IF(Parâmetros!$B$15=1,0,Parâmetros!$B$14)*Parâmetros!$B$10))*0.075-Parâmetros!$B$29,IF(MAX(0,K13-(MIN(K13,Parâmetros!$B$8)*Parâmetros!$B$7)-(IF(Parâmetros!$B$15=1,0,Parâmetros!$B$14)*Parâmetros!$B$10))<=Parâmetros!$B$27,MAX(0,K13-(MIN(K13,Parâmetros!$B$8)*Parâmetros!$B$7)-(IF(Parâmetros!$B$15=1,0,Parâmetros!$B$14)*Parâmetros!$B$10))*0.15-Parâmetros!$B$30,IF(MAX(0,K13-(MIN(K13,Parâmetros!$B$8)*Parâmetros!$B$7)-(IF(Parâmetros!$B$15=1,0,Parâmetros!$B$14)*Parâmetros!$B$10))<=Parâmetros!$B$28,MAX(0,K13-(MIN(K13,Parâmetros!$B$8)*Parâmetros!$B$7)-(IF(Parâmetros!$B$15=1,0,Parâmetros!$B$14)*Parâmetros!$B$10))*0.225-Parâmetros!$B$31,MAX(0,K13-(MIN(K13,Parâmetros!$B$8)*Parâmetros!$B$7)-(IF(Parâmetros!$B$15=1,0,Parâmetros!$B$14)*Parâmetros!$B$10))*0.275-Parâmetros!$B$32)))))-IF(K13<=Parâmetros!$B$34,Parâmetros!$B$35-Parâmetros!$B$36*K13,0))) | Q13: =MAX(0,B13-N13-K13) | R13: =B13-N13-O13-P13 | S13: =Parâmetros!$B$21 | T13: =IF(SUM(B5:B13)=0,0,SUM(S5:S13)/SUM(B5:B13)) | U13: =IF(T13>=Parâmetros!$B$6,"III","V") | V13: =IF(U13="III",B13*Parâmetros!$B$4,B13*Parâmetros!$B$5) | W13: =MIN(S13,Parâmetros!$B$8)*Parâmetros!$B$7 | X13: =IF(S13<=Parâmetros!$B$33,0,MAX(0,(IF(MAX(0,S13-(MIN(S13,Parâmetros!$B$8)*Parâmetros!$B$7)-(IF(Parâmetros!$B$15=1,0,Parâmetros!$B$14)*Parâmetros!$B$10))<=Parâmetros!$B$25,0,IF(MAX(0,S13-(MIN(S13,Parâmetros!$B$8)*Parâmetros!$B$7)-(IF(Parâmetros!$B$15=1,0,Parâmetros!$B$14)*Parâmetros!$B$10))<=Parâmetros!$B$26,MAX(0,S13-(MIN(S13,Parâmetros!$B$8)*Parâmetros!$B$7)-(IF(Parâmetros!$B$15=1,0,Parâmetros!$B$14)*Parâmetros!$B$10))*0.075-Parâmetros!$B$29,IF(MAX(0,S13-(MIN(S13,Parâmetros!$B$8)*Parâmetros!$B$7)-(IF(Parâmetros!$B$15=1,0,Parâmetros!$B$14)*Parâmetros!$B$10))<=Parâmetros!$B$27,MAX(0,S13-(MIN(S13,Parâmetros!$B$8)*Parâmetros!$B$7)-(IF(Parâmetros!$B$15=1,0,Parâmetros!$B$14)*Parâmetros!$B$10))*0.15-Parâmetros!$B$30,IF(MAX(0,S13-(MIN(S13,Parâmetros!$B$8)*Parâmetros!$B$7)-(IF(Parâmetros!$B$15=1,0,Parâmetros!$B$14)*Parâmetros!$B$10))<=Parâmetros!$B$28,MAX(0,S13-(MIN(S13,Parâmetros!$B$8)*Parâmetros!$B$7)-(IF(Parâmetros!$B$15=1,0,Parâmetros!$B$14)*Parâmetros!$B$10))*0.225-Parâmetros!$B$31,MAX(0,S13-(MIN(S13,Parâmetros!$B$8)*Parâmetros!$B$7)-(IF(Parâmetros!$B$15=1,0,Parâmetros!$B$14)*Parâmetros!$B$10))*0.275-Parâmetros!$B$32)))))-IF(S13<=Parâmetros!$B$34,Parâmetros!$B$35-Parâmetros!$B$36*S13,0))) | Y13: =MAX(0,B13-V13-S13) | Z13: =B13-V13-W13-X13
A14: 45931 | B14: =Notas!G15 | C14: =Parâmetros!$B$19 | D14: =IF(SUM(B5:B14)=0,0,SUM(C5:C14)/SUM(B5:B14)) | E14: =IF(D14>=Parâmetros!$B$6,"III","V") | F14: =IF(E14="III",B14*Parâmetros!$B$4,B14*Parâmetros!$B$5) | G14: =MIN(C14,Parâmetros!$B$8)*Parâmetros!$B$7 | H14: =IF(C14<=Parâmetros!$B$33,0,MAX(0,(IF(MAX(0,C14-(MIN(C14,Parâmetros!$B$8)*Parâmetros!$B$7)-(IF(Parâmetros!$B$15=1,0,Parâmetros!$B$14)*Parâmetros!$B$10))<=Parâmetros!$B$25,0,IF(MAX(0,C14-(MIN(C14,Parâmetros!$B$8)*Parâmetros!$B$7)-(IF(Parâmetros!$B$15=1,0,Parâmetros!$B$14)*Parâmetros!$B$10))<=Parâmetros!$B$26,MAX(0,C14-(MIN(C14,Parâmetros!$B$8)*Parâmetros!$B$7)-(IF(Parâmetros!$B$15=1,0,Parâmetros!$B$14)*Parâmetros!$B$10))*0.075-Parâmetros!$B$29,IF(MAX(0,C14-(MIN(C14,Parâmetros!$B$8)*Parâmetros!$B$7)-(IF(Parâmetros!$B$15=1,0,Parâmetros!$B$14)*Parâmetros!$B$10))<=Parâmetros!$B$27,MAX(0,C14-(MIN(C14,Parâmetros!$B$8)*Parâmetros!$B$7)-(IF(Parâmetros!$B$15=1,0,Parâmetros!$B$14)*Parâmetros!$B$10))*0.15-Parâmetros!$B$30,IF(MAX(0,C14-(MIN(C14,Parâmetros!$B$8)*Parâmetros!$B$7)-(IF(Parâmetros!$B$15=1,0,Parâmetros!$B$14)*Parâmetros!$B$10))<=Parâmetros!$B$28,MAX(0,C14-(MIN(C14,Parâmetros!$B$8)*Parâmetros!$B$7)-(IF(Parâmetros!$B$15=1,0,Parâmetros!$B$14)*Parâmetros!$B$10))*0.225-Parâmetros!$B$31,MAX(0,C14-(MIN(C14,Parâmetros!$B$8)*Parâmetros!$B$7)-(IF(Parâmetros!$B$15=1,0,Parâmetros!$B$14)*Parâmetros!$B$10))*0.275-Parâmetros!$B$32)))))-IF(C14<=Parâmetros!$B$34,Parâmetros!$B$35-Parâmetros!$B$36*C14,0))) | I14: =MAX(0,B14-F14-C14) | J14: =B14-F14-G14-H14 | K14: =IF(A14<Parâmetros!$B$23,Parâmetros!$B$19,MAX(Parâmetros!$B$22,Parâmetros!$B$6*SUM(B5:B14)-SUM(K5:K13))) | L14: =IF(SUM(B5:B14)=0,0,SUM(K5:K14)/SUM(B5:B14)) | M14: =IF(L14>=Parâmetros!$B$6,"III","V") | N14: =IF(M14="III",B14*Parâmetros!$B$4,B14*Parâmetros!$B$5) | O14: =MIN(K14,Parâmetros!$B$8)*Parâmetros!$B$7 | P14: =IF(K14<=Parâmetros!$B$33,0,MAX(0,(IF(MAX(0,K14-(MIN(K14,Parâmetros!$B$8)*Parâmetros!$B$7)-(IF(Parâmetros!$B$15=1,0,Parâmetros!$B$14)*Parâmetros!$B$10))<=Parâmetros!$B$25,0,IF(MAX(0,K14-(MIN(K14,Parâmetros!$B$8)*Parâmetros!$B$7)-(IF(Parâmetros!$B$15=1,0,Parâmetros!$B$14)*Parâmetros!$B$10))<=Parâmetros!$B$26,MAX(0,K14-(MIN(K14,Parâmetros!$B$8)*Parâmetros!$B$7)-(IF(Parâmetros!$B$15=1,0,Parâmetros!$B$14)*Parâmetros!$B$10))*0.075-Parâmetros!$B$29,IF(MAX(0,K14-(MIN(K14,Parâmetros!$B$8)*Parâmetros!$B$7)-(IF(Parâmetros!$B$15=1,0,Parâmetros!$B$14)*Parâmetros!$B$10))<=Parâmetros!$B$27,MAX(0,K14-(MIN(K14,Parâmetros!$B$8)*Parâmetros!$B$7)-(IF(Parâmetros!$B$15=1,0,Parâmetros!$B$14)*Parâmetros!$B$10))*0.15-Parâmetros!$B$30,IF(MAX(0,K14-(MIN(K14,Parâmetros!$B$8)*Parâmetros!$B$7)-(IF(Parâmetros!$B$15=1,0,Parâmetros!$B$14)*Parâmetros!$B$10))<=Parâmetros!$B$28,MAX(0,K14-(MIN(K14,Parâmetros!$B$8)*Parâmetros!$B$7)-(IF(Parâmetros!$B$15=1,0,Parâmetros!$B$14)*Parâmetros!$B$10))*0.225-Parâmetros!$B$31,MAX(0,K14-(MIN(K14,Parâmetros!$B$8)*Parâmetros!$B$7)-(IF(Parâmetros!$B$15=1,0,Parâmetros!$B$14)*Parâmetros!$B$10))*0.275-Parâmetros!$B$32)))))-IF(K14<=Parâmetros!$B$34,Parâmetros!$B$35-Parâmetros!$B$36*K14,0))) | Q14: =MAX(0,B14-N14-K14) | R14: =B14-N14-O14-P14 | S14: =Parâmetros!$B$21 | T14: =IF(SUM(B5:B14)=0,0,SUM(S5:S14)/SUM(B5:B14)) | U14: =IF(T14>=Parâmetros!$B$6,"III","V") | V14: =IF(U14="III",B14*Parâmetros!$B$4,B14*Parâmetros!$B$5) | W14: =MIN(S14,Parâmetros!$B$8)*Parâmetros!$B$7 | X14: =IF(S14<=Parâmetros!$B$33,0,MAX(0,(IF(MAX(0,S14-(MIN(S14,Parâmetros!$B$8)*Parâmetros!$B$7)-(IF(Parâmetros!$B$15=1,0,Parâmetros!$B$14)*Parâmetros!$B$10))<=Parâmetros!$B$25,0,IF(MAX(0,S14-(MIN(S14,Parâmetros!$B$8)*Parâmetros!$B$7)-(IF(Parâmetros!$B$15=1,0,Parâmetros!$B$14)*Parâmetros!$B$10))<=Parâmetros!$B$26,MAX(0,S14-(MIN(S14,Parâmetros!$B$8)*Parâmetros!$B$7)-(IF(Parâmetros!$B$15=1,0,Parâmetros!$B$14)*Parâmetros!$B$10))*0.075-Parâmetros!$B$29,IF(MAX(0,S14-(MIN(S14,Parâmetros!$B$8)*Parâmetros!$B$7)-(IF(Parâmetros!$B$15=1,0,Parâmetros!$B$14)*Parâmetros!$B$10))<=Parâmetros!$B$27,MAX(0,S14-(MIN(S14,Parâmetros!$B$8)*Parâmetros!$B$7)-(IF(Parâmetros!$B$15=1,0,Parâmetros!$B$14)*Parâmetros!$B$10))*0.15-Parâmetros!$B$30,IF(MAX(0,S14-(MIN(S14,Parâmetros!$B$8)*Parâmetros!$B$7)-(IF(Parâmetros!$B$15=1,0,Parâmetros!$B$14)*Parâmetros!$B$10))<=Parâmetros!$B$28,MAX(0,S14-(MIN(S14,Parâmetros!$B$8)*Parâmetros!$B$7)-(IF(Parâmetros!$B$15=1,0,Parâmetros!$B$14)*Parâmetros!$B$10))*0.225-Parâmetros!$B$31,MAX(0,S14-(MIN(S14,Parâmetros!$B$8)*Parâmetros!$B$7)-(IF(Parâmetros!$B$15=1,0,Parâmetros!$B$14)*Parâmetros!$B$10))*0.275-Parâmetros!$B$32)))))-IF(S14<=Parâmetros!$B$34,Parâmetros!$B$35-Parâmetros!$B$36*S14,0))) | Y14: =MAX(0,B14-V14-S14) | Z14: =B14-V14-W14-X14
A15: 45962 | B15: =Notas!G16 | C15: =Parâmetros!$B$19 | D15: =IF(SUM(B5:B15)=0,0,SUM(C5:C15)/SUM(B5:B15)) | E15: =IF(D15>=Parâmetros!$B$6,"III","V") | F15: =IF(E15="III",B15*Parâmetros!$B$4,B15*Parâmetros!$B$5) | G15: =MIN(C15,Parâmetros!$B$8)*Parâmetros!$B$7 | H15: =IF(C15<=Parâmetros!$B$33,0,MAX(0,(IF(MAX(0,C15-(MIN(C15,Parâmetros!$B$8)*Parâmetros!$B$7)-(IF(Parâmetros!$B$15=1,0,Parâmetros!$B$14)*Parâmetros!$B$10))<=Parâmetros!$B$25,0,IF(MAX(0,C15-(MIN(C15,Parâmetros!$B$8)*Parâmetros!$B$7)-(IF(Parâmetros!$B$15=1,0,Parâmetros!$B$14)*Parâmetros!$B$10))<=Parâmetros!$B$26,MAX(0,C15-(MIN(C15,Parâmetros!$B$8)*Parâmetros!$B$7)-(IF(Parâmetros!$B$15=1,0,Parâmetros!$B$14)*Parâmetros!$B$10))*0.075-Parâmetros!$B$29,IF(MAX(0,C15-(MIN(C15,Parâmetros!$B$8)*Parâmetros!$B$7)-(IF(Parâmetros!$B$15=1,0,Parâmetros!$B$14)*Parâmetros!$B$10))<=Parâmetros!$B$27,MAX(0,C15-(MIN(C15,Parâmetros!$B$8)*Parâmetros!$B$7)-(IF(Parâmetros!$B$15=1,0,Parâmetros!$B$14)*Parâmetros!$B$10))*0.15-Parâmetros!$B$30,IF(MAX(0,C15-(MIN(C15,Parâmetros!$B$8)*Parâmetros!$B$7)-(IF(Parâmetros!$B$15=1,0,Parâmetros!$B$14)*Parâmetros!$B$10))<=Parâmetros!$B$28,MAX(0,C15-(MIN(C15,Parâmetros!$B$8)*Parâmetros!$B$7)-(IF(Parâmetros!$B$15=1,0,Parâmetros!$B$14)*Parâmetros!$B$10))*0.225-Parâmetros!$B$31,MAX(0,C15-(MIN(C15,Parâmetros!$B$8)*Parâmetros!$B$7)-(IF(Parâmetros!$B$15=1,0,Parâmetros!$B$14)*Parâmetros!$B$10))*0.275-Parâmetros!$B$32)))))-IF(C15<=Parâmetros!$B$34,Parâmetros!$B$35-Parâmetros!$B$36*C15,0))) | I15: =MAX(0,B15-F15-C15) | J15: =B15-F15-G15-H15 | K15: =IF(A15<Parâmetros!$B$23,Parâmetros!$B$19,MAX(Parâmetros!$B$22,Parâmetros!$B$6*SUM(B5:B15)-SUM(K5:K14))) | L15: =IF(SUM(B5:B15)=0,0,SUM(K5:K15)/SUM(B5:B15)) | M15: =IF(L15>=Parâmetros!$B$6,"III","V") | N15: =IF(M15="III",B15*Parâmetros!$B$4,B15*Parâmetros!$B$5) | O15: =MIN(K15,Parâmetros!$B$8)*Parâmetros!$B$7 | P15: =IF(K15<=Parâmetros!$B$33,0,MAX(0,(IF(MAX(0,K15-(MIN(K15,Parâmetros!$B$8)*Parâmetros!$B$7)-(IF(Parâmetros!$B$15=1,0,Parâmetros!$B$14)*Parâmetros!$B$10))<=Parâmetros!$B$25,0,IF(MAX(0,K15-(MIN(K15,Parâmetros!$B$8)*Parâmetros!$B$7)-(IF(Parâmetros!$B$15=1,0,Parâmetros!$B$14)*Parâmetros!$B$10))<=Parâmetros!$B$26,MAX(0,K15-(MIN(K15,Parâmetros!$B$8)*Parâmetros!$B$7)-(IF(Parâmetros!$B$15=1,0,Parâmetros!$B$14)*Parâmetros!$B$10))*0.075-Parâmetros!$B$29,IF(MAX(0,K15-(MIN(K15,Parâmetros!$B$8)*Parâmetros!$B$7)-(IF(Parâmetros!$B$15=1,0,Parâmetros!$B$14)*Parâmetros!$B$10))<=Parâmetros!$B$27,MAX(0,K15-(MIN(K15,Parâmetros!$B$8)*Parâmetros!$B$7)-(IF(Parâmetros!$B$15=1,0,Parâmetros!$B$14)*Parâmetros!$B$10))*0.15-Parâmetros!$B$30,IF(MAX(0,K15-(MIN(K15,Parâmetros!$B$8)*Parâmetros!$B$7)-(IF(Parâmetros!$B$15=1,0,Parâmetros!$B$14)*Parâmetros!$B$10))<=Parâmetros!$B$28,MAX(0,K15-(MIN(K15,Parâmetros!$B$8)*Parâmetros!$B$7)-(IF(Parâmetros!$B$15=1,0,Parâmetros!$B$14)*Parâmetros!$B$10))*0.225-Parâmetros!$B$31,MAX(0,K15-(MIN(K15,Parâmetros!$B$8)*Parâmetros!$B$7)-(IF(Parâmetros!$B$15=1,0,Parâmetros!$B$14)*Parâmetros!$B$10))*0.275-Parâmetros!$B$32)))))-IF(K15<=Parâmetros!$B$34,Parâmetros!$B$35-Parâmetros!$B$36*K15,0))) | Q15: =MAX(0,B15-N15-K15) | R15: =B15-N15-O15-P15 | S15: =Parâmetros!$B$21 | T15: =IF(SUM(B5:B15)=0,0,SUM(S5:S15)/SUM(B5:B15)) | U15: =IF(T15>=Parâmetros!$B$6,"III","V") | V15: =IF(U15="III",B15*Parâmetros!$B$4,B15*Parâmetros!$B$5) | W15: =MIN(S15,Parâmetros!$B$8)*Parâmetros!$B$7 | X15: =IF(S15<=Parâmetros!$B$33,0,MAX(0,(IF(MAX(0,S15-(MIN(S15,Parâmetros!$B$8)*Parâmetros!$B$7)-(IF(Parâmetros!$B$15=1,0,Parâmetros!$B$14)*Parâmetros!$B$10))<=Parâmetros!$B$25,0,IF(MAX(0,S15-(MIN(S15,Parâmetros!$B$8)*Parâmetros!$B$7)-(IF(Parâmetros!$B$15=1,0,Parâmetros!$B$14)*Parâmetros!$B$10))<=Parâmetros!$B$26,MAX(0,S15-(MIN(S15,Parâmetros!$B$8)*Parâmetros!$B$7)-(IF(Parâmetros!$B$15=1,0,Parâmetros!$B$14)*Parâmetros!$B$10))*0.075-Parâmetros!$B$29,IF(MAX(0,S15-(MIN(S15,Parâmetros!$B$8)*Parâmetros!$B$7)-(IF(Parâmetros!$B$15=1,0,Parâmetros!$B$14)*Parâmetros!$B$10))<=Parâmetros!$B$27,MAX(0,S15-(MIN(S15,Parâmetros!$B$8)*Parâmetros!$B$7)-(IF(Parâmetros!$B$15=1,0,Parâmetros!$B$14)*Parâmetros!$B$10))*0.15-Parâmetros!$B$30,IF(MAX(0,S15-(MIN(S15,Parâmetros!$B$8)*Parâmetros!$B$7)-(IF(Parâmetros!$B$15=1,0,Parâmetros!$B$14)*Parâmetros!$B$10))<=Parâmetros!$B$28,MAX(0,S15-(MIN(S15,Parâmetros!$B$8)*Parâmetros!$B$7)-(IF(Parâmetros!$B$15=1,0,Parâmetros!$B$14)*Parâmetros!$B$10))*0.225-Parâmetros!$B$31,MAX(0,S15-(MIN(S15,Parâmetros!$B$8)*Parâmetros!$B$7)-(IF(Parâmetros!$B$15=1,0,Parâmetros!$B$14)*Parâmetros!$B$10))*0.275-Parâmetros!$B$32)))))-IF(S15<=Parâmetros!$B$34,Parâmetros!$B$35-Parâmetros!$B$36*S15,0))) | Y15: =MAX(0,B15-V15-S15) | Z15: =B15-V15-W15-X15
A16: 45992 | B16: =Notas!G17 | C16: =Parâmetros!$B$19 | D16: =IF(SUM(B5:B16)=0,0,SUM(C5:C16)/SUM(B5:B16)) | E16: =IF(D16>=Parâmetros!$B$6,"III","V") | F16: =IF(E16="III",B16*Parâmetros!$B$4,B16*Parâmetros!$B$5) | G16: =MIN(C16,Parâmetros!$B$8)*Parâmetros!$B$7 | H16: =IF(C16<=Parâmetros!$B$33,0,MAX(0,(IF(MAX(0,C16-(MIN(C16,Parâmetros!$B$8)*Parâmetros!$B$7)-(IF(Parâmetros!$B$15=1,0,Parâmetros!$B$14)*Parâmetros!$B$10))<=Parâmetros!$B$25,0,IF(MAX(0,C16-(MIN(C16,Parâmetros!$B$8)*Parâmetros!$B$7)-(IF(Parâmetros!$B$15=1,0,Parâmetros!$B$14)*Parâmetros!$B$10))<=Parâmetros!$B$26,MAX(0,C16-(MIN(C16,Parâmetros!$B$8)*Parâmetros!$B$7)-(IF(Parâmetros!$B$15=1,0,Parâmetros!$B$14)*Parâmetros!$B$10))*0.075-Parâmetros!$B$29,IF(MAX(0,C16-(MIN(C16,Parâmetros!$B$8)*Parâmetros!$B$7)-(IF(Parâmetros!$B$15=1,0,Parâmetros!$B$14)*Parâmetros!$B$10))<=Parâmetros!$B$27,MAX(0,C16-(MIN(C16,Parâmetros!$B$8)*Parâmetros!$B$7)-(IF(Parâmetros!$B$15=1,0,Parâmetros!$B$14)*Parâmetros!$B$10))*0.15-Parâmetros!$B$30,IF(MAX(0,C16-(MIN(C16,Parâmetros!$B$8)*Parâmetros!$B$7)-(IF(Parâmetros!$B$15=1,0,Parâmetros!$B$14)*Parâmetros!$B$10))<=Parâmetros!$B$28,MAX(0,C16-(MIN(C16,Parâmetros!$B$8)*Parâmetros!$B$7)-(IF(Parâmetros!$B$15=1,0,Parâmetros!$B$14)*Parâmetros!$B$10))*0.225-Parâmetros!$B$31,MAX(0,C16-(MIN(C16,Parâmetros!$B$8)*Parâmetros!$B$7)-(IF(Parâmetros!$B$15=1,0,Parâmetros!$B$14)*Parâmetros!$B$10))*0.275-Parâmetros!$B$32)))))-IF(C16<=Parâmetros!$B$34,Parâmetros!$B$35-Parâmetros!$B$36*C16,0))) | I16: =MAX(0,B16-F16-C16) | J16: =B16-F16-G16-H16 | K16: =IF(A16<Parâmetros!$B$23,Parâmetros!$B$19,MAX(Parâmetros!$B$22,Parâmetros!$B$6*SUM(B5:B16)-SUM(K5:K15))) | L16: =IF(SUM(B5:B16)=0,0,SUM(K5:K16)/SUM(B5:B16)) | M16: =IF(L16>=Parâmetros!$B$6,"III","V") | N16: =IF(M16="III",B16*Parâmetros!$B$4,B16*Parâmetros!$B$5) | O16: =MIN(K16,Parâmetros!$B$8)*Parâmetros!$B$7 | P16: =IF(K16<=Parâmetros!$B$33,0,MAX(0,(IF(MAX(0,K16-(MIN(K16,Parâmetros!$B$8)*Parâmetros!$B$7)-(IF(Parâmetros!$B$15=1,0,Parâmetros!$B$14)*Parâmetros!$B$10))<=Parâmetros!$B$25,0,IF(MAX(0,K16-(MIN(K16,Parâmetros!$B$8)*Parâmetros!$B$7)-(IF(Parâmetros!$B$15=1,0,Parâmetros!$B$14)*Parâmetros!$B$10))<=Parâmetros!$B$26,MAX(0,K16-(MIN(K16,Parâmetros!$B$8)*Parâmetros!$B$7)-(IF(Parâmetros!$B$15=1,0,Parâmetros!$B$14)*Parâmetros!$B$10))*0.075-Parâmetros!$B$29,IF(MAX(0,K16-(MIN(K16,Parâmetros!$B$8)*Parâmetros!$B$7)-(IF(Parâmetros!$B$15=1,0,Parâmetros!$B$14)*Parâmetros!$B$10))<=Parâmetros!$B$27,MAX(0,K16-(MIN(K16,Parâmetros!$B$8)*Parâmetros!$B$7)-(IF(Parâmetros!$B$15=1,0,Parâmetros!$B$14)*Parâmetros!$B$10))*0.15-Parâmetros!$B$30,IF(MAX(0,K16-(MIN(K16,Parâmetros!$B$8)*Parâmetros!$B$7)-(IF(Parâmetros!$B$15=1,0,Parâmetros!$B$14)*Parâmetros!$B$10))<=Parâmetros!$B$28,MAX(0,K16-(MIN(K16,Parâmetros!$B$8)*Parâmetros!$B$7)-(IF(Parâmetros!$B$15=1,0,Parâmetros!$B$14)*Parâmetros!$B$10))*0.225-Parâmetros!$B$31,MAX(0,K16-(MIN(K16,Parâmetros!$B$8)*Parâmetros!$B$7)-(IF(Parâmetros!$B$15=1,0,Parâmetros!$B$14)*Parâmetros!$B$10))*0.275-Parâmetros!$B$32)))))-IF(K16<=Parâmetros!$B$34,Parâmetros!$B$35-Parâmetros!$B$36*K16,0))) | Q16: =MAX(0,B16-N16-K16) | R16: =B16-N16-O16-P16 | S16: =Parâmetros!$B$21 | T16: =IF(SUM(B5:B16)=0,0,SUM(S5:S16)/SUM(B5:B16)) | U16: =IF(T16>=Parâmetros!$B$6,"III","V") | V16: =IF(U16="III",B16*Parâmetros!$B$4,B16*Parâmetros!$B$5) | W16: =MIN(S16,Parâmetros!$B$8)*Parâmetros!$B$7 | X16: =IF(S16<=Parâmetros!$B$33,0,MAX(0,(IF(MAX(0,S16-(MIN(S16,Parâmetros!$B$8)*Parâmetros!$B$7)-(IF(Parâmetros!$B$15=1,0,Parâmetros!$B$14)*Parâmetros!$B$10))<=Parâmetros!$B$25,0,IF(MAX(0,S16-(MIN(S16,Parâmetros!$B$8)*Parâmetros!$B$7)-(IF(Parâmetros!$B$15=1,0,Parâmetros!$B$14)*Parâmetros!$B$10))<=Parâmetros!$B$26,MAX(0,S16-(MIN(S16,Parâmetros!$B$8)*Parâmetros!$B$7)-(IF(Parâmetros!$B$15=1,0,Parâmetros!$B$14)*Parâmetros!$B$10))*0.075-Parâmetros!$B$29,IF(MAX(0,S16-(MIN(S16,Parâmetros!$B$8)*Parâmetros!$B$7)-(IF(Parâmetros!$B$15=1,0,Parâmetros!$B$14)*Parâmetros!$B$10))<=Parâmetros!$B$27,MAX(0,S16-(MIN(S16,Parâmetros!$B$8)*Parâmetros!$B$7)-(IF(Parâmetros!$B$15=1,0,Parâmetros!$B$14)*Parâmetros!$B$10))*0.15-Parâmetros!$B$30,IF(MAX(0,S16-(MIN(S16,Parâmetros!$B$8)*Parâmetros!$B$7)-(IF(Parâmetros!$B$15=1,0,Parâmetros!$B$14)*Parâmetros!$B$10))<=Parâmetros!$B$28,MAX(0,S16-(MIN(S16,Parâmetros!$B$8)*Parâmetros!$B$7)-(IF(Parâmetros!$B$15=1,0,Parâmetros!$B$14)*Parâmetros!$B$10))*0.225-Parâmetros!$B$31,MAX(0,S16-(MIN(S16,Parâmetros!$B$8)*Parâmetros!$B$7)-(IF(Parâmetros!$B$15=1,0,Parâmetros!$B$14)*Parâmetros!$B$10))*0.275-Parâmetros!$B$32)))))-IF(S16<=Parâmetros!$B$34,Parâmetros!$B$35-Parâmetros!$B$36*S16,0))) | Y16: =MAX(0,B16-V16-S16) | Z16: =B16-V16-W16-X16
